Workbook
Name CLASS: GOLF!$E:$E
Name CLASS: DELTA!$E:$E
Name NATURE: GOLF!$F:$F
Name CONFINEMENT: GOLF!$H:$H
Name NATURE: ECHO!$E:$E
Name NATURE: BRAVO!$F:$F
Name CONFINEMENT: ALFA!$H:$H
Name RANK: HAWK!$B:$B
Name RANK: CHARLIE!$B:$B
Name CONFINEMENT: HAWK!$H:$H
Name CLASS: BRAVO!$E:$E
Name CONFINEMENT: CHARLIE!$H:$H
Name CONFINEMENT: ECHO!$G:$G
Name NATURE: ALFA!$F:$F
Name NATURE: DELTA!$F:$F
Name REMARKS: BRAVO!$P:$P
Name REMARKS: DELTA!$P:$P
Name RANK: ECHO!$A:$A
Name NATURE: FOXTROT!$F:$F
Name CONFINEMENT: DELTA!$H:$H
Name REMARKS: CHARLIE!$P:$P
Name NamedRange1: BRAVO!$B:$B
Name REMARKS: FOXTROT!$P:$P
Name RANK: FOXTROT!$B:$B
Name CLASS: CHARLIE!$E:$E
Name REMARKS: ECHO!$O:$O
Name RANK: DELTA!$B:$B
Name NATURE: CHARLIE!$F:$F
Name CLASS: ECHO!$D:$D
Name REMARKS: HAWK!$P:$P
Name RANK: ALFA!$B:$B
Name CONFINEMENT: FOXTROT!$H:$H
Name CLASS: FOXTROT!$E:$E
Name CONFINEMENT: BRAVO!$H:$H
Name NATURE: HAWK!$F:$F
Name CLASS: HAWK!$E:$E
Name RANK: BRAVO!$B:$B
Name RANK: GOLF!$B:$B
Name REMARKS: GOLF!$P:$P
Name CLASS: ALFA!$E:$E
Name REMARKS: ALFA!$P:$P

Sheet TOTAL 
B9: TOTAL NUMBER OF TOURING CADETS | J9: TOTAL NUMBER OF CONFINED CADETS | R9: TOTAL NUMBER OF TOURING/CONFINED CADETS
B12: =SUM(SUMMARY!F48:J55,SUMMARY!BB20:BE21) -> 65 | J12: =sum(SUMMARY!L48:L55,SUMMARY!BB41) -> 228 | R12: =SUMMARY!R57 -> 58

Sheet SUMMARY
B2: .
E4: ALFA | K4: BRAVO | Q4: CHARLIE | W4: DELTA | AC4: ECHO | AI4: FOXTROT | AO4: GOLF | AU4: HAWK | BA4: CONDUCT
E7: SUMMARY | K7: SUMMARY | Q7: SUMMARY | W7: SUMMARY | AC7: SUMMARY | AI7: SUMMARY | AO7: SUMMARY | AU7: SUMMARY | BA7: SUMMARY
E9: NATURE OF REPORT | F9: 1CL | G9: 2CL | H9: 3CL | I9: 4CL | K9: NATURE OF REPORT | L9: 1CL | M9: 2CL | N9: 3CL | O9: 4CL | Q9: NATURE OF REPORT | R9: 1CL | S9: 2CL | T9: 3CL | U9: 4CL | W9: NATURE OF REPORT | X9: 1CL | Y9: 2CL | Z9: 3CL | AA9: 4CL | AC9: NATURE OF REPORT | AD9: 1CL | AE9: 2CL | AF9: 3CL | AG9: 4CL | AI9: NATURE OF REPORT | AJ9: 1CL | AK9: 2CL | AL9: 3CL | AM9: 4CL | AO9: NATURE OF REPORT | AP9: 1CL | AQ9: 2CL | AR9: 3CL | AS9: 4CL | AU9: NATURE OF REPORT | AV9: 1CL | AW9: 2CL | AX9: 3CL | AY9: 4CL | BA9: NATURE OF REPORT | BB9: 1CL | BC9: 2CL | BD9: 3CL | BE9: 4CL
E10: UNNACCOUNTED/ABSENT | F10: =COUNTIFS(RANK,"1CL",NATURE,"UNNACCOUNTED/ABSENT",ALFA!N:N,">0") -> 0 | G10: =COUNTIFS(RANK,"2CL",NATURE,"UNNACCOUNTED/ABSENT",ALFA!N:N,">0") -> 0 | H10: =COUNTIFS(RANK,"3CL",NATURE,"UNNACCOUNTED/ABSENT",ALFA!N:N,">0") -> 0 | I10: =COUNTIFS(RANK,"4CL",NATURE,"UNNACCOUNTED/ABSENT",REMARKS,"ONGOING") -> 0 | K10: UNNACCOUNTED/ABSENT | L10: =COUNTIFS(BRAVO!RANK,"1CL",BRAVO!NATURE,"UNNACCOUNTED/ABSENT",BRAVO!N:N,">0") -> 0 | M10: =COUNTIFS(BRAVO!RANK,"2CL",BRAVO!NATURE,"UNNACCOUNTED/ABSENT",BRAVO!N:N,">0") -> 0 | N10: =COUNTIFS(BRAVO!RANK,"3CL",BRAVO!NATURE,"UNNACCOUNTED/ABSENT",BRAVO!N:N,">0") -> 0 | O10: =COUNTIFS(BRAVO!RANK,"4CL",BRAVO!NATURE,"UNNACCOUNTED/ABSENT",BRAVO!REMARKS,"ONGOING") -> 0 | Q10: UNNACCOUNTED/ABSENT | R10: =COUNTIFS(CHARLIE!RANK,"1CL",CHARLIE!NATURE,"UNNACCOUNTED/ABSENT",CHARLIE!N:N,">0") -> 2 | S10: =COUNTIFS(CHARLIE!RANK,"2CL",CHARLIE!NATURE,"UNNACCOUNTED/ABSENT",CHARLIE!N:N,">0") -> 2 | T10: =COUNTIFS(CHARLIE!RANK,"3CL",CHARLIE!NATURE,"UNNACCOUNTED/ABSENT",CHARLIE!N:N,">0") -> 3 | U10: =COUNTIFS(CHARLIE!RANK,"4CL",CHARLIE!NATURE,"UNNACCOUNTED/ABSENT",CHARLIE!REMARKS,"ONGOING") -> 0 | W10: UNNACCOUNTED/ABSENT | X10: =COUNTIFS(DELTA!RANK,"1CL",DELTA!NATURE,"UNNACCOUNTED/ABSENT",DELTA!N:N,">0") -> 0 | Y10: =COUNTIFS(DELTA!RANK,"2CL",DELTA!NATURE,"UNNACCOUNTED/ABSENT",DELTA!N:N,">0") -> 0 | Z10: =COUNTIFS(DELTA!RANK,"3CL",DELTA!NATURE,"UNNACCOUNTED/ABSENT",DELTA!N:N,">0") -> 1 | AA10: =COUNTIFS(DELTA!RANK,"4CL",DELTA!NATURE,"UNNACCOUNTED/ABSENT",DELTA!REMARKS,"ONGOING") -> 1 | AC10: UNNACCOUNTED/ABSENT | AD10: =COUNTIFS(ECHO!RANK,"1CL",ECHO!NATURE,"UNNACCOUNTED/ABSENT",ECHO!M:M,">0") -> 0 | AE10: =COUNTIFS(ECHO!RANK,"2CL",ECHO!NATURE,"UNNACCOUNTED/ABSENT",ECHO!M:M,">0") -> 0 | AF10: =COUNTIFS(ECHO!RANK,"3CL",ECHO!NATURE,"UNNACCOUNTED/ABSENT",ECHO!M:M,">0") -> 0 | AG10: =COUNTIFS(ECHO!RANK,"4CL",ECHO!NATURE,"UNNACCOUNTED/ABSENT",ECHO!REMARKS,"ONGOING") -> 0 | AI10: UNNACCOUNTED/ABSENT | AJ10: =COUNTIFS(FOXTROT!RANK,"1CL",FOXTROT!NATURE,"UNNACCOUNTED/ABSENT",FOXTROT!N:N,">0") -> 0 | AK10: =COUNTIFS(FOXTROT!RANK,"2CL",FOXTROT!NATURE,"UNNACCOUNTED/ABSENT",FOXTROT!N:N,">0") -> 0 | AL10: =COUNTIFS(FOXTROT!RANK,"3CL",FOXTROT!NATURE,"UNNACCOUNTED/ABSENT",FOXTROT!N:N,">0") -> 0 | AM10: =COUNTIFS(FOXTROT!RANK,"4CL",FOXTROT!NATURE,"UNNACCOUNTED/ABSENT",FOXTROT!REMARKS,"ONGOING") -> 6 | AO10: UNNACCOUNTED/ABSENT | AP10: =COUNTIFS(GOLF!RANK,"1CL",GOLF!NATURE,"UNNACCOUNTED/ABSENT",GOLF!N:N,">0") -> 0 | AQ10: =COUNTIFS(GOLF!RANK,"2CL",GOLF!NATURE,"UNNACCOUNTED/ABSENT",GOLF!N:N,">0") -> 0 | AR10: =COUNTIFS(GOLF!RANK,"3CL",GOLF!NATURE,"UNNACCOUNTED/ABSENT",GOLF!N:N,">0") -> 0 | AS10: =COUNTIFS(GOLF!RANK,"4CL",GOLF!NATURE,"UNNACCOUNTED/ABSENT",GOLF!REMARKS,"ONGOING") -> 0 | AU10: UNNACCOUNTED/ABSENT | AV10: =COUNTIFS(HAWK!RANK,"1CL",HAWK!NATURE,"UNNACCOUNTED/ABSENT",HAWK!N:N,">0") -> 0 | AW10: =COUNTIFS(HAWK!RANK,"2CL",HAWK!NATURE,"UNNACCOUNTED/ABSENT",HAWK!N:N,">0") -> 0 | AX10: =COUNTIFS(HAWK!RANK,"3CL",HAWK!NATURE,"UNNACCOUNTED/ABSENT",HAWK!N:N,">0") -> 0 | AY10: =COUNTIFS(HAWK!RANK,"4CL",HAWK!NATURE,"UNNACCOUNTED/ABSENT",HAWK!REMARKS,"ONGOING") -> 2 | BA10: UNNACCOUNTED/ABSENT | BB10: =COUNTIFS(#REF!,"1CL",#REF!,"UNNACCOUNTED/ABSENT",#REF!,"ONGOING") -> 0 | BC10: =COUNTIFS(#REF!,"2CL",#REF!,"UNNACCOUNTED/ABSENT",#REF!,"ONGOING") -> 0 | BD10: =COUNTIFS(#REF!,"3CL",#REF!,"UNNACCOUNTED/ABSENT",#REF!,"ONGOING") -> 0 | BE10: =COUNTIFS(#REF!,"4CL",#REF!,"UNNACCOUNTED/ABSENT",#REF!,"ONGOING") -> 0
E11: LATE | F11: =COUNTIFS(RANK,"1CL",NATURE,"LATE",ALFA!N:N,">0") -> 0 | G11: =COUNTIFS(RANK,"2CL",NATURE,"LATE",ALFA!N:N,">0") -> 0 | H11: =COUNTIFS(RANK,"3CL",NATURE,"LATE",ALFA!N:N,">0") -> 2 | I11: =COUNTIFS(RANK,"4CL",NATURE,"LATE",REMARKS,"ONGOING") -> 0 | K11: LATE | L11: =COUNTIFS(BRAVO!RANK,"1CL",BRAVO!NATURE,"LATE",BRAVO!N:N,">0") -> 0 | M11: =COUNTIFS(BRAVO!RANK,"2CL",BRAVO!NATURE,"LATE",BRAVO!N:N,">0") -> 0 | N11: =COUNTIFS(BRAVO!RANK,"3CL",BRAVO!NATURE,LATE,BRAVO!N:N,">0") -> 0 | O11: =COUNTIFS(BRAVO!RANK,"4CL",BRAVO!NATURE,LATE,BRAVO!REMARKS,"ONGOING") -> 0 | Q11: LATE | R11: =COUNTIFS(CHARLIE!RANK,"1CL",CHARLIE!NATURE,"LATE",CHARLIE!N:N,">0") -> 0 | S11: =COUNTIFS(CHARLIE!RANK,"2CL",CHARLIE!NATURE,"LATE",CHARLIE!N:N,">0") -> 1 | T11: =COUNTIFS(CHARLIE!RANK,"3CL",CHARLIE!NATURE,"LATE",CHARLIE!N:N,">0") -> 5 | U11: =COUNTIFS(CHARLIE!RANK,"4CL",CHARLIE!NATURE,"LATE",CHARLIE!REMARKS,"ONGOING") -> 0 | W11: LATE | X11: =COUNTIFS(DELTA!RANK,"1CL",DELTA!NATURE,"LATE",DELTA!N:N,">0") -> 0 | Y11: =COUNTIFS(DELTA!RANK,"2CL",DELTA!NATURE,"LATE",DELTA!N:N,">0") -> 0 | Z11: =COUNTIFS(DELTA!RANK,"3CL",DELTA!NATURE,"LATE",DELTA!N:N,">0") -> 4 | AA11: =COUNTIFS(DELTA!RANK,"4CL",DELTA!NATURE,"LATE",DELTA!REMARKS,"ONGOING") -> 1 | AC11: LATE | AD11: =COUNTIFS(ECHO!RANK,"1CL",ECHO!NATURE,"LATE",ECHO!M:M,">0") -> 0 | AE11: =COUNTIFS(ECHO!RANK,"2CL",ECHO!NATURE,"LATE",ECHO!M:M,">0") -> 0 | AF11: =COUNTIFS(ECHO!RANK,"3CL",ECHO!NATURE,"LATE",ECHO!M:M,">0") -> 0 | AG11: =COUNTIFS(ECHO!RANK,"4CL",ECHO!NATURE,"LATE",ECHO!REMARKS,"ONGOING") -> 0 | AI11: LATE | AJ11: =COUNTIFS(FOXTROT!RANK,"1CL",FOXTROT!NATURE,"LATE",FOXTROT!N:N,">0") -> 0 | AK11: =COUNTIFS(FOXTROT!RANK,"2CL",FOXTROT!NATURE,"LATE",FOXTROT!N:N,">0") -> 0 | AL11: =COUNTIFS(FOXTROT!RANK,"3CL",FOXTROT!NATURE,"LATE",FOXTROT!N:N,">0") -> 0 | AM11: =COUNTIFS(FOXTROT!RANK,"4CL",FOXTROT!NATURE,"LATE",FOXTROT!REMARKS,"ONGOING") -> 1 | AO11: LATE | AP11: =COUNTIFS(GOLF!RANK,"1CL",GOLF!NATURE,"LATE",GOLF!N:N,">0") -> 0 | AQ11: =COUNTIFS(GOLF!RANK,"2CL",GOLF!NATURE,"LATE",GOLF!N:N,">0") -> 0 | AR11: =COUNTIFS(GOLF!RANK,"3CL",GOLF!NATURE,"LATE",GOLF!N:N,">0") -> 0 | AS11: =COUNTIFS(GOLF!RANK,"4CL",GOLF!NATURE,"LATE",GOLF!REMARKS,"ONGOING") -> 0 | AU11: LATE | AV11: =COUNTIFS(HAWK!RANK,"1CL",HAWK!NATURE,"LATE",HAWK!N:N,">0") -> 0 | AW11: =COUNTIFS(HAWK!RANK,"2CL",HAWK!NATURE,"LATE",HAWK!N:N,">0") -> 0 | AX11: =COUNTIFS(HAWK!RANK,"3CL",HAWK!NATURE,"LATE",HAWK!N:N,">0") -> 0 | AY11: =COUNTIFS(HAWK!RANK,"4CL",HAWK!NATURE,"LATE",HAWK!REMARKS,"ONGOING") -> 0 | BA11: LATE | BB11: =COUNTIFS(#REF!,"1CL",#REF!,"LATE",#REF!,"ONGOING") -> 0 | BC11: =COUNTIFS(#REF!,"2CL",#REF!,"LATE",#REF!,"ONGOING") -> 0 | BD11: =COUNTIFS(#REF!,"3CL",#REF!,"LATE",#REF!,"ONGOING") -> 0 | BE11: =COUNTIFS(#REF!,"4CL",#REF!,"LATE",#REF!,"ONGOING") -> 0
E12: NEGLIGENCE OF DUTY | F12: =COUNTIFS(RANK,"1CL",NATURE,"NEGLIGENCE OF DUTY",ALFA!N:N,">0") -> 0 | G12: =COUNTIFS(RANK,"2CL",NATURE,"NEGLIGENCE OF DUTY",ALFA!N:N,">0") -> 0 | H12: =COUNTIFS(RANK,"3CL",NATURE,"NEGLIGENCE OF DUTY",ALFA!N:N,">0") -> 0 | I12: =COUNTIFS(RANK,"4CL",NATURE,"NEGLIGENCE OF DUTY",REMARKS,"ONGOING") -> 0 | K12: NEGLIGENCE OF DUTY | L12: =COUNTIFS(BRAVO!RANK,"1CL",BRAVO!NATURE,"NEGLIGENCE OF DUTY",BRAVO!N:N,">0") -> 0 | M12: =COUNTIFS(BRAVO!RANK,"2CL",BRAVO!NATURE,"NEGLIGENCE OF DUTY",BRAVO!N:N,">0") -> 0 | N12: =COUNTIFS(BRAVO!RANK,"3CL",BRAVO!NATURE,"NEGLIGENCE OF DUTY",BRAVO!N:N,">0") -> 0 | O12: =COUNTIFS(BRAVO!RANK,"4CL",BRAVO!NATURE,"NEGLIGENCE OF DUTY",BRAVO!REMARKS,"ONGOING") -> 0 | Q12: NEGLIGENCE OF DUTY | R12: =COUNTIFS(CHARLIE!RANK,"1CL",CHARLIE!NATURE,"NEGLIGENCE OF DUTY",CHARLIE!N:N,">0") -> 0 | S12: =COUNTIFS(CHARLIE!RANK,"2CL",CHARLIE!NATURE,"NEGLIGENCE OF DUTY",CHARLIE!N:N,">0") -> 0 | T12: =COUNTIFS(CHARLIE!RANK,"3CL",CHARLIE!NATURE,"NEGLIGENCE OF DUTY",CHARLIE!N:N,">0") -> 2 | U12: =COUNTIFS(CHARLIE!RANK,"4CL",CHARLIE!NATURE,"NEGLIGENCE OF DUTY",CHARLIE!REMARKS,"ONGOING") -> 0 | W12: NEGLIGENCE OF DUTY | X12: =COUNTIFS(DELTA!RANK,"1CL",DELTA!NATURE,"NEGLIGENCE OF DUTY",DELTA!N:N,">0") -> 0 | Y12: =COUNTIFS(DELTA!RANK,"2CL",DELTA!NATURE,"NEGLIGENCE OF DUTY",DELTA!N:N,">0") -> 0 | Z12: =COUNTIFS(DELTA!RANK,"3CL",DELTA!NATURE,"NEGLIGENCE OF DUTY",DELTA!N:N,">0") -> 2 | AA12: =COUNTIFS(DELTA!RANK,"4CL",DELTA!NATURE,"NEGLIGENCE OF DUTY",DELTA!REMARKS,"ONGOING") -> 0 | AC12: NEGLIGENCE OF DUTY | AD12: =COUNTIFS(ECHO!RANK,"1CL",ECHO!NATURE,"NEGLIGENCE OF DUTY",ECHO!M:M,">0") -> 0 | AE12: =COUNTIFS(ECHO!RANK,"2CL",ECHO!NATURE,"NEGLIGENCE OF DUTY",ECHO!M:M,">0") -> 0 | AF12: =COUNTIFS(ECHO!RANK,"3CL",ECHO!NATURE,"NEGLIGENCE OF DUTY",ECHO!M:M,">0") -> 0 | AG12: =COUNTIFS(ECHO!RANK,"4CL",ECHO!NATURE,"NEGLIGENCE OF DUTY",ECHO!REMARKS,"ONGOING") -> 0 | AI12: NEGLIGENCE OF DUTY | AJ12: =COUNTIFS(FOXTROT!RANK,"1CL",FOXTROT!NATURE,"NEGLIGENCE OF DUTY",FOXTROT!N:N,">0") -> 0 | AK12: =COUNTIFS(FOXTROT!RANK,"2CL",FOXTROT!NATURE,"NEGLIGENCE OF DUTY",FOXTROT!N:N,">0") -> 0 | AL12: =COUNTIFS(FOXTROT!RANK,"3CL",FOXTROT!NATURE,"NEGLIGENCE OF DUTY",FOXTROT!N:N,">0") -> 0 | AM12: =COUNTIFS(FOXTROT!RANK,"4CL",FOXTROT!NATURE,"NEGLIGENCE OF DUTY",FOXTROT!REMARKS,"ONGOING") -> 0 | AO12: NEGLIGENCE OF DUTY | AP12: =COUNTIFS(GOLF!RANK,"1CL",GOLF!NATURE,"NEGLIGENCE OF DUTY",GOLF!N:N,">0") -> 0 | AQ12: =COUNTIFS(GOLF!RANK,"2CL",GOLF!NATURE,"NEGLIGENCE OF DUTY",GOLF!N:N,">0") -> 0 | AR12: =COUNTIFS(GOLF!RANK,"3CL",GOLF!NATURE,"NEGLIGENCE OF DUTY",GOLF!N:N,">0") -> 0 | AS12: =COUNTIFS(GOLF!RANK,"4CL",GOLF!NATURE,"NEGLIGENCE OF DUTY",GOLF!REMARKS,"ONGOING") -> 0 | AU12: NEGLIGENCE OF DUTY | AV12: =COUNTIFS(HAWK!RANK,"1CL",HAWK!NATURE,"NEGLIGENCE OF DUTY",HAWK!N:N,">0") -> 0 | AW12: =COUNTIFS(HAWK!RANK,"2CL",HAWK!NATURE,"NEGLIGENCE OF DUTY",HAWK!N:N,">0") -> 0 | AX12: =COUNTIFS(HAWK!RANK,"3CL",HAWK!NATURE,"NEGLIGENCE OF DUTY",HAWK!N:N,">0") -> 0 | AY12: =COUNTIFS(HAWK!RANK,"4CL",HAWK!NATURE,"NEGLIGENCE OF DUTY",HAWK!REMARKS,"ONGOING") -> 0 | BA12: NEGLIGENCE OF DUTY | BB12: =COUNTIFS(#REF!,"1CL",#REF!,"NEGLIGENCE OF DUTY",#REF!,"ONGOING") -> 0 | BC12: =COUNTIFS(#REF!,"2CL",#REF!,"NEGLIGENCE OF DUTY",#REF!,"ONGOING") -> 0 | BD12: =COUNTIFS(#REF!,"3CL",#REF!,"NEGLIGENCE OF DUTY",#REF!,"ONGOING") -> 0 | BE12: =COUNTIFS(#REF!,"4CL",#REF!,"NEGLIGENCE OF DUTY",#REF!,"ONGOING") -> 0
E13: POSSESSING/USING UNAUTHORIZED ITEM | F13: =COUNTIFS(RANK,"1CL",NATURE,"POSSESSING/USING UNAUTHORIZED ITEM",ALFA!N:N,">0") -> 0 | G13: =COUNTIFS(RANK,"2CL",NATURE,"POSSESSING/USING UNAUTHORIZED ITEM",ALFA!N:N,">0") -> 1 | H13: =COUNTIFS(RANK,"3CL",NATURE,"POSSESSING/USING UNAUTHORIZED ITEM",ALFA!N:N,">0") -> 0 | I13: =COUNTIFS(RANK,"4CL",NATURE,"POSSESSING/USING UNAUTHORIZED ITEM",REMARKS,"ONGOING") -> 0 | K13: POSSESSING/USING UNAUTHORIZED ITEM | L13: =COUNTIFS(BRAVO!RANK,"1CL",BRAVO!NATURE,"POSSESSING/USING UNAUTHORIZED ITEM",BRAVO!N:N,">0") -> 0 | M13: =COUNTIFS(BRAVO!RANK,"2CL",BRAVO!NATURE,"POSSESSING/USING UNAUTHORIZED ITEM",BRAVO!N:N,">0") -> 0 | N13: =COUNTIFS(BRAVO!RANK,"3CL",BRAVO!NATURE,"POSSESSING/USING UNAUTHORIZED ITEM",BRAVO!N:N,">0") -> 0 | O13: =COUNTIFS(BRAVO!RANK,"4CL",BRAVO!NATURE,"POSSESSING/USING UNAUTHORIZED ITEM",BRAVO!REMARKS,"ONGOING") -> 0 | Q13: POSSESSING/USING UNAUTHORIZED ITEM | R13: =COUNTIFS(CHARLIE!RANK,"1CL",CHARLIE!NATURE,"POSSESSING/USING UNAUTHORIZED ITEM",CHARLIE!N:N,">0") -> 0 | S13: =COUNTIFS(CHARLIE!RANK,"2CL",CHARLIE!NATURE,"POSSESSING/USING UNAUTHORIZED ITEM",CHARLIE!N:N,">0") -> 1 | T13: =COUNTIFS(CHARLIE!RANK,"3CL",CHARLIE!NATURE,"POSSESSING/USING UNAUTHORIZED ITEM",CHARLIE!N:N,">0") -> 2 | U13: =COUNTIFS(CHARLIE!RANK,"4CL",CHARLIE!NATURE,"POSSESSING/USING UNAUTHORIZED ITEM",CHARLIE!REMARKS,"ONGOING") -> 0 | W13: POSSESSING/USING UNAUTHORIZED ITEM | X13: =COUNTIFS(DELTA!RANK,"1CL",DELTA!NATURE,"POSSESSING/USING UNAUTHORIZED ITEM",DELTA!N:N,">0") -> 0 | Y13: =COUNTIFS(DELTA!RANK,"2CL",DELTA!NATURE,"POSSESSING/USING UNAUTHORIZED ITEM",DELTA!N:N,">0") -> 1 | Z13: =COUNTIFS(DELTA!RANK,"3CL",DELTA!NATURE,"POSSESSING/USING UNAUTHORIZED ITEM",DELTA!N:N,">0") -> 0 | AA13: =COUNTIFS(DELTA!RANK,"4CL",DELTA!NATURE,"POSSESSING/USING UNAUTHORIZED ITEM",DELTA!REMARKS,"ONGOING") -> 0 | AC13: POSSESSING/USING UNAUTHORIZED ITEM | AD13: =COUNTIFS(ECHO!RANK,"1CL",ECHO!NATURE,"POSSESSING/USING UNAUTHORIZED ITEM",ECHO!M:M,">0") -> 0 | AE13: =COUNTIFS(ECHO!RANK,"2CL",ECHO!NATURE,"POSSESSING/USING UNAUTHORIZED ITEM",ECHO!M:M,">0") -> 1 | AF13: =COUNTIFS(ECHO!RANK,"3CL",ECHO!NATURE,"POSSESSING/USING UNAUTHORIZED ITEM",ECHO!M:M,">0") -> 0 | AG13: =COUNTIFS(ECHO!RANK,"4CL",ECHO!NATURE,"POSSESSING/USING UNAUTHORIZED ITEM",ECHO!REMARKS,"ONGOING") -> 0 | AI13: POSSESSING/USING UNAUTHORIZED ITEM | AJ13: =COUNTIFS(FOXTROT!RANK,"1CL",FOXTROT!NATURE,"POSSESSING/USING UNAUTHORIZED ITEM",FOXTROT!N:N,">0") -> 0 | AK13: =COUNTIFS(FOXTROT!RANK,"2CL",FOXTROT!NATURE,"POSSESSING/USING UNAUTHORIZED ITEM",FOXTROT!N:N,">0") -> 1 | AL13: =COUNTIFS(FOXTROT!RANK,"3CL",FOXTROT!NATURE,"POSSESSING/USING UNAUTHORIZED ITEM",FOXTROT!N:N,">0") -> 0 | AM13: =COUNTIFS(FOXTROT!RANK,"4CL",FOXTROT!NATURE,"POSSESSING/USING UNAUTHORIZED ITEM",FOXTROT!REMARKS,"ONGOING") -> 0 | AO13: POSSESSING/USING UNAUTHORIZED ITEM | AP13: =COUNTIFS(GOLF!RANK,"1CL",GOLF!NATURE,"POSSESSING/USING UNAUTHORIZED ITEM",GOLF!N:N,">0") -> 0 | AQ13: =COUNTIFS(GOLF!RANK,"2CL",GOLF!NATURE,"POSSESSING/USING UNAUTHORIZED ITEM",GOLF!N:N,">0") -> 0 | AR13: =COUNTIFS(GOLF!RANK,"3CL",GOLF!NATURE,"POSSESSING/USING UNAUTHORIZED ITEM",GOLF!N:N,">0") -> 0 | AS13: =COUNTIFS(GOLF!RANK,"4CL",GOLF!NATURE,"POSSESSING/USING UNAUTHORIZED ITEM",GOLF!REMARKS,"ONGOING") -> 0 | AU13: POSSESSING/USING UNAUTHORIZED ITEM | AV13: =COUNTIFS(HAWK!RANK,"1CL",HAWK!NATURE,"POSSESSING/USING UNAUTHORIZED ITEM",HAWK!N:N,">0") -> 0 | AW13: =COUNTIFS(HAWK!RANK,"2CL",HAWK!NATURE,"POSSESSING/USING UNAUTHORIZED ITEM",HAWK!N:N,">0") -> 0 | AX13: =COUNTIFS(HAWK!RANK,"3CL",HAWK!NATURE,"POSSESSING/USING UNAUTHORIZED ITEM",HAWK!N:N,">0") -> 1 | AY13: =COUNTIFS(HAWK!RANK,"4CL",HAWK!NATURE,"POSSESSING/USING UNAUTHORIZED ITEM",HAWK!REMARKS,"ONGOING") -> 0 | BA13: POSSESSING/USING UNAUTHORIZED ITEM | BB13: =COUNTIFS(#REF!,"1CL",#REF!,"POSSESSING/USING UNAUTHORIZED ITEM",#REF!,"ONGOING") -> 0 | BC13: =COUNTIFS(#REF!,"2CL",#REF!,"POSSESSING/USING UNAUTHORIZED ITEM",#REF!,"ONGOING") -> 0 | BD13: =COUNTIFS(#REF!,"3CL",#REF!,"POSSESSING/USING UNAUTHORIZED ITEM",#REF!,"ONGOING") -> 0 | BE13: =COUNTIFS(#REF!,"4CL",#REF!,"POSSESSING/USING UNAUTHORIZED ITEM",#REF!,"ONGOING") -> 0
E14: DOING UNAUTHORIZED THINGS | F14: =COUNTIFS(RANK,"1CL",NATURE,"DOING UNAUTHORIZED THINGS",ALFA!N:N,">0") -> 0 | G14: =COUNTIFS(RANK,"2CL",NATURE,"DOING UNAUTHORIZED THINGS",ALFA!N:N,">0") -> 3 | H14: =COUNTIFS(RANK,"3CL",NATURE,"DOING UNAUTHORIZED THINGS",ALFA!N:N,">0") -> 0 | I14: =COUNTIFS(RANK,"4CL",NATURE,"DOING UNAUTHORIZED THINGS",REMARKS,"ONGOING") -> 0 | K14: DOING UNAUTHORIZED THINGS | L14: =COUNTIFS(BRAVO!RANK,"1CL",BRAVO!NATURE,"DOING UNAUTHORIZED THINGS",BRAVO!N:N,">0") -> 0 | M14: =COUNTIFS(BRAVO!RANK,"2CL",BRAVO!NATURE,"DOING UNAUTHORIZED THINGS",BRAVO!N:N,">0") -> 0 | N14: =COUNTIFS(BRAVO!RANK,"3CL",BRAVO!NATURE,"DOING UNAUTHORIZED THINGS",BRAVO!N:N,">0") -> 0 | O14: =COUNTIFS(BRAVO!RANK,"4CL",BRAVO!NATURE,"DOING UNAUTHORIZED THINGS",BRAVO!REMARKS,"ONGOING") -> 0 | Q14: DOING UNAUTHORIZED THINGS | R14: =COUNTIFS(CHARLIE!RANK,"1CL",CHARLIE!NATURE,"DOING UNAUTHORIZED THINGS",CHARLIE!N:N,">0") -> 1 | S14: =COUNTIFS(CHARLIE!RANK,"2CL",CHARLIE!NATURE,"DOING UNAUTHORIZED THINGS",CHARLIE!N:N,">0") -> 1 | T14: =COUNTIFS(CHARLIE!RANK,"3CL",CHARLIE!NATURE,"DOING UNAUTHORIZED THINGS",CHARLIE!N:N,">0") -> 4 | U14: =COUNTIFS(CHARLIE!RANK,"4CL",CHARLIE!NATURE,"DOING UNAUTHORIZED THINGS",CHARLIE!REMARKS,"ONGOING") -> 0 | W14: DOING UNAUTHORIZED THINGS | X14: =COUNTIFS(DELTA!RANK,"1CL",DELTA!NATURE,"DOING UNAUTHORIZED THINGS",DELTA!N:N,">0") -> 1 | Y14: =COUNTIFS(DELTA!RANK,"2CL",DELTA!NATURE,"DOING UNAUTHORIZED THINGS",DELTA!N:N,">0") -> 2 | Z14: =COUNTIFS(DELTA!RANK,"3CL",DELTA!NATURE,"DOING UNAUTHORIZED THINGS",DELTA!N:N,">0") -> 0 | AA14: =COUNTIFS(DELTA!RANK,"4CL",DELTA!NATURE,"DOING UNAUTHORIZED THINGS",DELTA!REMARKS,"ONGOING") -> 1 | AC14: DOING UNAUTHORIZED THINGS | AD14: =COUNTIFS(ECHO!RANK,"1CL",ECHO!NATURE,"DOING UNAUTHORIZED THINGS",ECHO!M:M,">0") -> 0 | AE14: =COUNTIFS(ECHO!RANK,"2CL",ECHO!NATURE,"DOING UNAUTHORIZED THINGS",ECHO!M:M,">0") -> 1 | AF14: =COUNTIFS(ECHO!RANK,"3CL",ECHO!NATURE,"DOING UNAUTHORIZED THINGS",ECHO!M:M,">0") -> 0 | AG14: =COUNTIFS(ECHO!RANK,"4CL",ECHO!NATURE,"DOING UNAUTHORIZED THINGS",ECHO!REMARKS,"ONGOING") -> 0 | AI14: DOING UNAUTHORIZED THINGS | AJ14: =COUNTIFS(FOXTROT!RANK,"1CL",FOXTROT!NATURE,"DOING UNAUTHORIZED THINGS",FOXTROT!N:N,">0") -> 0 | AK14: =COUNTIFS(FOXTROT!RANK,"2CL",FOXTROT!NATURE,"DOING UNAUTHORIZED THINGS",FOXTROT!N:N,">0") -> 1 | AL14: =COUNTIFS(FOXTROT!RANK,"3CL",FOXTROT!NATURE,"DOING UNAUTHORIZED THINGS",FOXTROT!N:N,">0") -> 0 | AM14: =COUNTIFS(FOXTROT!RANK,"4CL",FOXTROT!NATURE,"DOING UNAUTHORIZED THINGS",FOXTROT!REMARKS,"ONGOING") -> 1 | AO14: DOING UNAUTHORIZED THINGS | AP14: =COUNTIFS(GOLF!RANK,"1CL",GOLF!NATURE,"DOING UNAUTHORIZED THINGS",GOLF!N:N,">0") -> 0 | AQ14: =COUNTIFS(GOLF!RANK,"2CL",GOLF!NATURE,"DOING UNAUTHORIZED THINGS",GOLF!N:N,">0") -> 0 | AR14: =COUNTIFS(GOLF!RANK,"3CL",GOLF!NATURE,"DOING UNAUTHORIZED THINGS",GOLF!N:N,">0") -> 0 | AS14: =COUNTIFS(GOLF!RANK,"4CL",GOLF!NATURE,"DOING UNAUTHORIZED THINGS",GOLF!REMARKS,"ONGOING") -> 0 | AU14: DOING UNAUTHORIZED THINGS | AV14: =COUNTIFS(HAWK!RANK,"1CL",HAWK!NATURE,"DOING UNAUTHORIZED THINGS",HAWK!N:N,">0") -> 0 | AW14: =COUNTIFS(HAWK!RANK,"2CL",HAWK!NATURE,"DOING UNAUTHORIZED THINGS",HAWK!N:N,">0") -> 1 | AX14: =COUNTIFS(HAWK!RANK,"3CL",HAWK!NATURE,"DOING UNAUTHORIZED THINGS",HAWK!N:N,">0") -> 0 | AY14: =COUNTIFS(HAWK!RANK,"4CL",HAWK!NATURE,"DOING UNAUTHORIZED THINGS",HAWK!REMARKS,"ONGOING") -> 0 | BA14: DOING UNAUTHORIZED THINGS | BB14: =COUNTIFS(#REF!,"1CL",#REF!,"DOING UNAUTHORIZED THINGS",#REF!,"ONGOING") -> 0 | BC14: =COUNTIFS(#REF!,"2CL",#REF!,"DOING UNAUTHORIZED THINGS",#REF!,"ONGOING") -> 0 | BD14: =COUNTIFS(#REF!,"3CL",#REF!,"DOING UNAUTHORIZED THINGS",#REF!,"ONGOING") -> 0 | BE14: =COUNTIFS(#REF!,"4CL",#REF!,"DOING UNAUTHORIZED THINGS",#REF!,"ONGOING") -> 0
E15: SEXUAL MISCONDUCT/HARASSMENT | F15: =COUNTIFS(RANK,"1CL",NATURE,"SEXUAL MISCONDUCT/HARASSMENT",ALFA!N:N,">0") -> 0 | G15: =COUNTIFS(RANK,"2CL",NATURE,"SEXUAL MISCONDUCT/HARASSMENT",ALFA!N:N,">0") -> 0 | H15: =COUNTIFS(RANK,"3CL",NATURE,"SEXUAL MISCONDUCT/HARASSMENT",ALFA!N:N,">0") -> 0 | I15: =COUNTIFS(RANK,"4CL",NATURE,"SEXUAL MISCONDUCT/HARASSMENT",REMARKS,"ONGOING") -> 0 | K15: SEXUAL MISCONDUCT/HARASSMENT | L15: =COUNTIFS(BRAVO!RANK,"1CL",BRAVO!NATURE,"SEXUAL MISCONDUCT/HARASSMENT",BRAVO!N:N,">0") -> 0 | M15: =COUNTIFS(BRAVO!RANK,"2CL",BRAVO!NATURE,"SEXUAL MISCONDUCT/HARASSMENT",BRAVO!N:N,">0") -> 0 | N15: =COUNTIFS(BRAVO!RANK,"3CL",BRAVO!NATURE,"SEXUAL MISCONDUCT/HARASSMENT",BRAVO!N:N,">0") -> 0 | O15: =COUNTIFS(BRAVO!RANK,"4CL",BRAVO!NATURE,"SEXUAL MISCONDUCT/HARASSMENT",BRAVO!REMARKS,"ONGOING") -> 0 | Q15: SEXUAL MISCONDUCT/HARASSMENT | R15: =COUNTIFS(CHARLIE!RANK,"1CL",CHARLIE!NATURE,"SEXUAL MISCONDUCT/HARASSMENT",CHARLIE!N:N,">0") -> 0 | S15: =COUNTIFS(CHARLIE!RANK,"2CL",CHARLIE!NATURE,"SEXUAL MISCONDUCT/HARASSMENT",CHARLIE!N:N,">0") -> 0 | T15: =COUNTIFS(CHARLIE!RANK,"3CL",CHARLIE!NATURE,"SEXUAL MISCONDUCT/HARASSMENT",CHARLIE!N:N,">0") -> 0 | U15: =COUNTIFS(CHARLIE!RANK,"4CL",CHARLIE!NATURE,"SEXUAL MISCONDUCT/HARASSMENT",CHARLIE!REMARKS,"ONGOING") -> 0 | W15: SEXUAL MISCONDUCT/HARASSMENT | X15: =COUNTIFS(DELTA!RANK,"1CL",DELTA!NATURE,"SEXUAL MISCONDUCT/HARASSMENT",DELTA!N:N,">0") -> 0 | Y15: =COUNTIFS(DELTA!RANK,"2CL",DELTA!NATURE,"SEXUAL MISCONDUCT/HARASSMENT",DELTA!N:N,">0") -> 0 | Z15: =COUNTIFS(DELTA!RANK,"3CL",DELTA!NATURE,"SEXUAL MISCONDUCT/HARASSMENT",DELTA!N:N,">0") -> 0 | AA15: =COUNTIFS(DELTA!RANK,"4CL",DELTA!NATURE,"SEXUAL MISCONDUCT/HARASSMENT",DELTA!REMARKS,"ONGOING") -> 0 | AC15: SEXUAL MISCONDUCT/HARASSMENT | AD15: =COUNTIFS(ECHO!RANK,"1CL",ECHO!NATURE,"SEXUAL MISCONDUCT/HARASSMENT",ECHO!M:M,">0") -> 0 | AE15: =COUNTIFS(ECHO!RANK,"2CL",ECHO!NATURE,"SEXUAL MISCONDUCT/HARASSMENT",ECHO!M:M,">0") -> 0 | AF15: =COUNTIFS(ECHO!RANK,"3CL",ECHO!NATURE,"SEXUAL MISCONDUCT/HARASSMENT",ECHO!M:M,">0") -> 0 | AG15: =COUNTIFS(ECHO!RANK,"4CL",ECHO!NATURE,"SEXUAL MISCONDUCT/HARASSMENT",ECHO!REMARKS,"ONGOING") -> 0 | AI15: SEXUAL MISCONDUCT/HARASSMENT | AJ15: =COUNTIFS(FOXTROT!RANK,"1CL",FOXTROT!NATURE,"SEXUAL MISCONDUCT/HARASSMENT",FOXTROT!N:N,">0") -> 0 | AK15: =COUNTIFS(FOXTROT!RANK,"2CL",FOXTROT!NATURE,"SEXUAL MISCONDUCT/HARASSMENT",FOXTROT!N:N,">0") -> 0 | AL15: =COUNTIFS(FOXTROT!RANK,"3CL",FOXTROT!NATURE,"SEXUAL MISCONDUCT/HARASSMENT",FOXTROT!N:N,">0") -> 0 | AM15: =COUNTIFS(FOXTROT!RANK,"4CL",FOXTROT!NATURE,"SEXUAL MISCONDUCT/HARASSMENT",FOXTROT!REMARKS,"ONGOING") -> 0 | AO15: SEXUAL MISCONDUCT/HARASSMENT | AP15: =COUNTIFS(GOLF!RANK,"1CL",GOLF!NATURE,"SEXUAL MISCONDUCT/HARASSMENT",GOLF!N:N,">0") -> 0 | AQ15: =COUNTIFS(GOLF!RANK,"2CL",GOLF!NATURE,"SEXUAL MISCONDUCT/HARASSMENT",GOLF!N:N,">0") -> 0 | AR15: =COUNTIFS(GOLF!RANK,"3CL",GOLF!NATURE,"SEXUAL MISCONDUCT/HARASSMENT",GOLF!N:N,">0") -> 0 | AS15: =COUNTIFS(GOLF!RANK,"4CL",GOLF!NATURE,"SEXUAL MISCONDUCT/HARASSMENT",GOLF!REMARKS,"ONGOING") -> 0 | AU15: SEXUAL MISCONDUCT/HARASSMENT | AV15: =COUNTIFS(HAWK!RANK,"1CL",HAWK!NATURE,"SEXUAL MISCONDUCT/HARASSMENT",HAWK!N:N,">0") -> 0 | AW15: =COUNTIFS(HAWK!RANK,"2CL",HAWK!NATURE,"SEXUAL MISCONDUCT/HARASSMENT",HAWK!N:N,">0") -> 0 | AX15: =COUNTIFS(HAWK!RANK,"3CL",HAWK!NATURE,"SEXUAL MISCONDUCT/HARASSMENT",HAWK!N:N,">0") -> 0 | AY15: =COUNTIFS(HAWK!RANK,"4CL",HAWK!NATURE,"SEXUAL MISCONDUCT/HARASSMENT",HAWK!REMARKS,"ONGOING") -> 0 | BA15: SEXUAL MISCONDUCT/HARASSMENT | BB15: =COUNTIFS(#REF!,"1CL",#REF!,"SEXUAL MISCONDUCT/HARASSMENT",#REF!,"ONGOING") -> 0 | BC15: =COUNTIFS(#REF!,"2CL",#REF!,"SEXUAL MISCONDUCT/HARASSMENT",#REF!,"ONGOING") -> 0 | BD15: =COUNTIFS(#REF!,"3CL",#REF!,"SEXUAL MISCONDUCT/HARASSMENT",#REF!,"ONGOING") -> 0 | BE15: =COUNTIFS(#REF!,"4CL",#REF!,"SEXUAL MISCONDUCT/HARASSMENT",#REF!,"ONGOING") -> 0
E16: MALTREATMENT/NTP/CTP | F16: =COUNTIFS(RANK,"1CL",NATURE,"UMALTREATMENT/NTP/CTP",ALFA!N:N,">0") -> 0 | G16: =COUNTIFS(RANK,"2CL",NATURE,"MALTREATMENT/NTP/CTP",ALFA!N:N,">0") -> 0 | H16: =COUNTIFS(RANK,"3CL",NATURE,"MALTREATMENT/NTP/CTP",ALFA!N:N,">0") -> 0 | I16: =COUNTIFS(RANK,"4CL",NATURE,"MALTREATMENT/NTP/CTP",REMARKS,"ONGOING") -> 0 | K16: MALTREATMENT/NTP/CTP | L16: =COUNTIFS(BRAVO!RANK,"1CL",BRAVO!NATURE,"MALTREATMENT/NTP/CTP",BRAVO!N:N,">0") -> 0 | M16: =COUNTIFS(BRAVO!RANK,"2CL",BRAVO!NATURE,"MALTREATMENT/NTP/CTP",BRAVO!N:N,">0") -> 0 | N16: =COUNTIFS(BRAVO!RANK,"3CL",BRAVO!NATURE,"MALTREATMENT/NTP/CTP",BRAVO!N:N,">0") -> 0 | O16: =COUNTIFS(BRAVO!RANK,"4CL",BRAVO!NATURE,"MALTREATMENT/NTP/CTP",BRAVO!REMARKS,"ONGOING") -> 0 | Q16: MALTREATMENT/NTP/CTP | R16: =COUNTIFS(CHARLIE!RANK,"1CL",CHARLIE!NATURE,"MALTREATMENT/NTP/CTP",CHARLIE!N:N,">0") -> 0 | S16: =COUNTIFS(CHARLIE!RANK,"2CL",CHARLIE!NATURE,"MALTREATMENT/NTP/CTP",CHARLIE!N:N,">0") -> 0 | T16: =COUNTIFS(CHARLIE!RANK,"3CL",CHARLIE!NATURE,"MALTREATMENT/NTP/CTP",CHARLIE!N:N,">0") -> 0 | U16: =COUNTIFS(CHARLIE!RANK,"4CL",CHARLIE!NATURE,"MALTREATMENT/NTP/CTP",CHARLIE!REMARKS,"ONGOING") -> 0 | W16: MALTREATMENT/NTP/CTP | X16: =COUNTIFS(DELTA!RANK,"1CL",DELTA!NATURE,"MALTREATMENT/NTP/CTP",DELTA!N:N,">0") -> 0 | Y16: =COUNTIFS(DELTA!RANK,"2CL",DELTA!NATURE,"MALTREATMENT/NTP/CTP",DELTA!N:N,">0") -> 1 | Z16: =COUNTIFS(DELTA!RANK,"3CL",DELTA!NATURE,"MALTREATMENT/NTP/CTP",DELTA!N:N,">0") -> 0 | AA16: =COUNTIFS(DELTA!RANK,"4CL",DELTA!NATURE,"MALTREATMENT/NTP/CTP",DELTA!REMARKS,"ONGOING") -> 0 | AC16: MALTREATMENT/NTP/CTP | AD16: =COUNTIFS(ECHO!RANK,"1CL",ECHO!NATURE,"MALTREATMENT/NTP/CTP",ECHO!M:M,">0") -> 0 | AE16: =COUNTIFS(ECHO!RANK,"2CL",ECHO!NATURE,"MALTREATMENT/NTP/CTP",ECHO!M:M,">0") -> 0 | AF16: =COUNTIFS(ECHO!RANK,"3CL",ECHO!NATURE,"MALTREATMENT/NTP/CTP",ECHO!M:M,">0") -> 0 | AG16: =COUNTIFS(ECHO!RANK,"4CL",ECHO!NATURE,"MALTREATMENT/NTP/CTP",ECHO!REMARKS,"ONGOING") -> 0 | AI16: MALTREATMENT/NTP/CTP | AJ16: =COUNTIFS(FOXTROT!RANK,"1CL",FOXTROT!NATURE,"MALTREATMENT/NTP/CTP",FOXTROT!N:N,">0") -> 0 | AK16: =COUNTIFS(FOXTROT!RANK,"2CL",FOXTROT!NATURE,"MALTREATMENT/NTP/CTP",FOXTROT!N:N,">0") -> 1 | AL16: =COUNTIFS(FOXTROT!RANK,"3CL",FOXTROT!NATURE,"MALTREATMENT/NTP/CTP",FOXTROT!N:N,">0") -> 0 | AM16: =COUNTIFS(FOXTROT!RANK,"4CL",FOXTROT!NATURE,"MALTREATMENT/NTP/CTP",FOXTROT!REMARKS,"ONGOING") -> 0 | AO16: MALTREATMENT/NTP/CTP | AP16: =COUNTIFS(GOLF!RANK,"1CL",GOLF!NATURE,"MALTREATMENT/NTP/CTP",GOLF!N:N,">0") -> 0 | AQ16: =COUNTIFS(GOLF!RANK,"2CL",GOLF!NATURE,"MALTREATMENT/NTP/CTP",GOLF!N:N,">0") -> 0 | AR16: =COUNTIFS(GOLF!RANK,"3CL",GOLF!NATURE,"MALTREATMENT/NTP/CTP",GOLF!N:N,">0") -> 0 | AS16: =COUNTIFS(GOLF!RANK,"4CL",GOLF!NATURE,"MALTREATMENT/NTP/CTP",GOLF!REMARKS,"ONGOING") -> 0 | AU16: MALTREATMENT/NTP/CTP | AV16: =COUNTIFS(HAWK!RANK,"1CL",HAWK!NATURE,"MALTREATMENT/NTP/CTP",HAWK!N:N,">0") -> 0 | AW16: =COUNTIFS(HAWK!RANK,"2CL",HAWK!NATURE,"MALTREATMENT/NTP/CTP",HAWK!N:N,">0") -> 0 | AX16: =COUNTIFS(HAWK!RANK,"3CL",HAWK!NATURE,"MALTREATMENT/NTP/CTP",HAWK!N:N,">0") -> 0 | AY16: =COUNTIFS(HAWK!RANK,"4CL",HAWK!NATURE,"MALTREATMENT/NTP/CTP",HAWK!REMARKS,"ONGOING") -> 0 | BA16: MALTREATMENT/NTP/CTP | BB16: =COUNTIFS(#REF!,"1CL",#REF!,"MALTREATMENT/NTP/CTP",#REF!,"ONGOING") -> 0 | BC16: =COUNTIFS(#REF!,"2CL",#REF!,"MALTREATMENT/NTP/CTP",#REF!,"ONGOING") -> 0 | BD16: =COUNTIFS(#REF!,"3CL",#REF!,"MALTREATMENT/NTP/CTP",#REF!,"ONGOING") -> 0 | BE16: =COUNTIFS(#REF!,"4CL",#REF!,"MALTREATMENT/NTP/CTP",#REF!,"ONGOING") -> 0
E17: HONOR | F17: =COUNTIFS(RANK,"1CL",NATURE,"HONOR",ALFA!N:N,">0") -> 0 | G17: =COUNTIFS(RANK,"2CL",NATURE,"HONOR",ALFA!N:N,">0") -> 0 | H17: =COUNTIFS(RANK,"3CL",NATURE,"HONOR",ALFA!N:N,">0") -> 0 | I17: =COUNTIFS(RANK,"4CL",NATURE,"HONOR",REMARKS,"ONGOING") -> 0 | K17: HONOR | L17: =COUNTIFS(BRAVO!RANK,"1CL",BRAVO!NATURE,"HONOR",BRAVO!N:N,">0") -> 0 | M17: =COUNTIFS(BRAVO!RANK,"2CL",BRAVO!NATURE,"HONOR",BRAVO!N:N,">0") -> 0 | N17: =COUNTIFS(BRAVO!RANK,"3CL",BRAVO!NATURE,"HONOR",BRAVO!N:N,">0") -> 0 | O17: =COUNTIFS(BRAVO!RANK,"4CL",BRAVO!NATURE,"HONOR",BRAVO!REMARKS,"ONGOING") -> 0 | Q17: HONOR | R17: =COUNTIFS(CHARLIE!RANK,"1CL",CHARLIE!NATURE,"HONOR",CHARLIE!N:N,">0") -> 0 | S17: =COUNTIFS(CHARLIE!RANK,"2CL",CHARLIE!NATURE,"HONOR",CHARLIE!N:N,">0") -> 0 | T17: =COUNTIFS(CHARLIE!RANK,"3CL",CHARLIE!NATURE,"HONOR",CHARLIE!N:N,">0") -> 0 | U17: =COUNTIFS(CHARLIE!RANK,"4CL",CHARLIE!NATURE,"HONOR",CHARLIE!REMARKS,"ONGOING") -> 0 | W17: HONOR | X17: =COUNTIFS(DELTA!RANK,"1CL",DELTA!NATURE,"HONOR",DELTA!N:N,">0") -> 0 | Y17: =COUNTIFS(DELTA!RANK,"2CL",DELTA!NATURE,"HONOR",DELTA!N:N,">0") -> 0 | Z17: =COUNTIFS(DELTA!RANK,"3CL",DELTA!NATURE,"HONOR",DELTA!N:N,">0") -> 0 | AA17: =COUNTIFS(DELTA!RANK,"4CL",DELTA!NATURE,"HONOR",DELTA!REMARKS,"ONGOING") -> 0 | AC17: HONOR | AD17: =COUNTIFS(ECHO!RANK,"1CL",ECHO!NATURE,"HONOR",ECHO!M:M,">0") -> 0 | AE17: =COUNTIFS(ECHO!RANK,"2CL",ECHO!NATURE,"HONOR",ECHO!M:M,">0") -> 0 | AF17: =COUNTIFS(ECHO!RANK,"3CL",ECHO!NATURE,"HONOR",ECHO!M:M,">0") -> 0 | AG17: =COUNTIFS(ECHO!RANK,"4CL",ECHO!NATURE,"HONOR",ECHO!REMARKS,"ONGOING") -> 0 | AI17: HONOR | AJ17: =COUNTIFS(FOXTROT!RANK,"1CL",FOXTROT!NATURE,"HONOR",FOXTROT!N:N,">0") -> 0 | AK17: =COUNTIFS(FOXTROT!RANK,"2CL",FOXTROT!NATURE,"HONOR",FOXTROT!N:N,">0") -> 0 | AL17: =COUNTIFS(FOXTROT!RANK,"3CL",FOXTROT!NATURE,"HONOR",FOXTROT!N:N,">0") -> 0 | AM17: =COUNTIFS(FOXTROT!RANK,"4CL",FOXTROT!NATURE,"HONOR",FOXTROT!REMARKS,"ONGOING") -> 0 | AO17: HONOR | AP17: =COUNTIFS(GOLF!RANK,"1CL",GOLF!NATURE,"HONOR",GOLF!N:N,">0") -> 0 | AQ17: =COUNTIFS(GOLF!RANK,"2CL",GOLF!NATURE,"HONOR",GOLF!N:N,">0") -> 0 | AR17: =COUNTIFS(GOLF!RANK,"3CL",GOLF!NATURE,"HONOR",GOLF!N:N,">0") -> 0 | AS17: =COUNTIFS(GOLF!RANK,"4CL",GOLF!NATURE,"HONOR",GOLF!REMARKS,"ONGOING") -> 0 | AU17: HONOR | AV17: =COUNTIFS(HAWK!RANK,"1CL",HAWK!NATURE,"HONOR",HAWK!N:N,">0") -> 0 | AW17: =COUNTIFS(HAWK!RANK,"2CL",HAWK!NATURE,"HONOR",HAWK!N:N,">0") -> 0 | AX17: =COUNTIFS(HAWK!RANK,"3CL",HAWK!NATURE,"HONOR",HAWK!N:N,">0") -> 0 | AY17: =COUNTIFS(HAWK!RANK,"4CL",HAWK!NATURE,"HONOR",HAWK!REMARKS,"ONGOING") -> 0 | BA17: HONOR | BB17: =COUNTIFS(#REF!,"1CL",#REF!,"HONOR",#REF!,"ONGOING") -> 0 | BC17: =COUNTIFS(#REF!,"2CL",#REF!,"HONOR",#REF!,"ONGOING") -> 0 | BD17: =COUNTIFS(#REF!,"3CL",#REF!,"HONOR",#REF!,"ONGOING") -> 0 | BE17: =COUNTIFS(#REF!,"4CL",#REF!,"HONOR",#REF!,"ONGOING") -> 0
E18: CLEANLINESS OF ROOM | F18: =COUNTIFS(RANK,"1CL",NATURE,"CLEANLINESS OF ROOM",ALFA!N:N,">0") -> 0 | G18: =COUNTIFS(RANK,"2CL",NATURE,"CLEANLINESS OF ROOM",ALFA!N:N,">0") -> 0 | H18: =COUNTIFS(RANK,"3CL",NATURE,"CLEANLINESS OF ROOM",ALFA!N:N,">0") -> 0 | I18: =COUNTIFS(RANK,"4CL",NATURE,"CLEANLINESS OF ROOM",REMARKS,"ONGOING") -> 0 | K18: CLEANLINESS OF ROOM | L18: =COUNTIFS(BRAVO!RANK,"1CL",BRAVO!NATURE,"CLEANLINESS OF ROOM",BRAVO!N:N,">0") -> 0 | M18: =COUNTIFS(BRAVO!RANK,"2CL",BRAVO!NATURE,"CLEANLINESS OF ROOM",BRAVO!N:N,">0") -> 0 | N18: =COUNTIFS(BRAVO!RANK,"3CL",BRAVO!NATURE,"CLEANLINESS OF ROOM",BRAVO!N:N,">0") -> 0 | O18: =COUNTIFS(BRAVO!RANK,"4CL",BRAVO!NATURE,"CLEANLINESS OF ROOM",BRAVO!REMARKS,"ONGOING") -> 0 | Q18: CLEANLINESS OF ROOM | R18: =COUNTIFS(CHARLIE!RANK,"1CL",CHARLIE!NATURE,"CLEANLINESS OF ROOM",CHARLIE!N:N,">0") -> 0 | S18: =COUNTIFS(CHARLIE!RANK,"2CL",CHARLIE!NATURE,"CLEANLINESS OF ROOM",CHARLIE!N:N,">0") -> 0 | T18: =COUNTIFS(CHARLIE!RANK,"3CL",CHARLIE!NATURE,"CLEANLINESS OF ROOM",CHARLIE!N:N,">0") -> 0 | U18: =COUNTIFS(CHARLIE!RANK,"4CL",CHARLIE!NATURE,"CLEANLINESS OF ROOM",CHARLIE!REMARKS,"ONGOING") -> 0 | W18: CLEANLINESS OF ROOM | X18: =COUNTIFS(DELTA!RANK,"1CL",DELTA!NATURE,"CLEANLINESS OF ROOM",DELTA!N:N,">0") -> 0 | Y18: =COUNTIFS(DELTA!RANK,"2CL",DELTA!NATURE,"CLEANLINESS OF ROOM",DELTA!N:N,">0") -> 0 | Z18: =COUNTIFS(DELTA!RANK,"3CL",DELTA!NATURE,"CLEANLINESS OF ROOM",DELTA!N:N,">0") -> 0 | AA18: =COUNTIFS(DELTA!RANK,"4CL",DELTA!NATURE,"CLEANLINESS OF ROOM",DELTA!REMARKS,"ONGOING") -> 0 | AC18: CLEANLINESS OF ROOM | AD18: =COUNTIFS(ECHO!RANK,"1CL",ECHO!NATURE,"CLEANLINESS OF ROOM",ECHO!M:M,">0") -> 0 | AE18: =COUNTIFS(ECHO!RANK,"2CL",ECHO!NATURE,"CLEANLINESS OF ROOM",ECHO!M:M,">0") -> 0 | AF18: =COUNTIFS(ECHO!RANK,"3CL",ECHO!NATURE,"CLEANLINESS OF ROOM",ECHO!M:M,">0") -> 0 | AG18: =COUNTIFS(ECHO!RANK,"4CL",ECHO!NATURE,"CLEANLINESS OF ROOM",ECHO!REMARKS,"ONGOING") -> 0 | AI18: CLEANLINESS OF ROOM | AJ18: =COUNTIFS(FOXTROT!RANK,"1CL",FOXTROT!NATURE,"CLEANLINESS OF ROOM",FOXTROT!N:N,">0") -> 0 | AK18: =COUNTIFS(FOXTROT!RANK,"2CL",FOXTROT!NATURE,"CLEANLINESS OF ROOM",FOXTROT!N:N,">0") -> 0 | AL18: =COUNTIFS(FOXTROT!RANK,"3CL",FOXTROT!NATURE,"CLEANLINESS OF ROOM",FOXTROT!N:N,">0") -> 0 | AM18: =COUNTIFS(FOXTROT!RANK,"4CL",FOXTROT!NATURE,"CLEANLINESS OF ROOM",FOXTROT!REMARKS,"ONGOING") -> 0 | AO18: CLEANLINESS OF ROOM | AP18: =COUNTIFS(GOLF!RANK,"1CL",GOLF!NATURE,"CLEANLINESS OF ROOM",GOLF!N:N,">0") -> 0 | AQ18: =COUNTIFS(GOLF!RANK,"2CL",GOLF!NATURE,"CLEANLINESS OF ROOM",GOLF!N:N,">0") -> 0 | AR18: =COUNTIFS(GOLF!RANK,"3CL",GOLF!NATURE,"CLEANLINESS OF ROOM",GOLF!N:N,">0") -> 0 | AS18: =COUNTIFS(GOLF!RANK,"4CL",GOLF!NATURE,"CLEANLINESS OF ROOM",GOLF!REMARKS,"ONGOING") -> 0 | AU18: CLEANLINESS OF ROOM | AV18: =COUNTIFS(HAWK!RANK,"1CL",HAWK!NATURE,"CLEANLINESS OF ROOM",HAWK!N:N,">0") -> 0 | AW18: =COUNTIFS(HAWK!RANK,"2CL",HAWK!NATURE,"CLEANLINESS OF ROOM",HAWK!N:N,">0") -> 0 | AX18: =COUNTIFS(HAWK!RANK,"3CL",HAWK!NATURE,"CLEANLINESS OF ROOM",HAWK!N:N,">0") -> 0 | AY18: =COUNTIFS(HAWK!RANK,"4CL",HAWK!NATURE,"CLEANLINESS OF ROOM",HAWK!REMARKS,"ONGOING") -> 0 | BA18: CLEANLINESS OF ROOM | BB18: =COUNTIFS(#REF!,"1CL",#REF!,"CLEANLINESS OF ROOM",#REF!,"ONGOING") -> 0 | BC18: =COUNTIFS(#REF!,"2CL",#REF!,"CLEANLINESS OF ROOM",#REF!,"ONGOING") -> 0 | BD18: =COUNTIFS(#REF!,"3CL",#REF!,"CLEANLINESS OF ROOM",#REF!,"ONGOING") -> 0 | BE18: =COUNTIFS(#REF!,"4CL",#REF!,"CLEANLINESS OF ROOM",#REF!,"ONGOING") -> 0
E19: UNIFORM | F19: =COUNTIFS(RANK,"1CL",NATURE,"UNIFORM",ALFA!N:N,">0") -> 0 | G19: =COUNTIFS(RANK,"2CL",NATURE,"UNIFORM",ALFA!N:N,">0") -> 0 | H19: =COUNTIFS(RANK,"3CL",NATURE,"UNIFORM",ALFA!N:N,">0") -> 0 | I19: =COUNTIFS(RANK,"4CL",NATURE,"UNIFORM",REMARKS,"ONGOING") -> 0 | K19: UNIFORM | L19: =COUNTIFS(BRAVO!RANK,"1CL",BRAVO!NATURE,"UNIFORM",BRAVO!N:N,">0") -> 0 | M19: =COUNTIFS(BRAVO!RANK,"2CL",BRAVO!NATURE,"UNIFORM",BRAVO!N:N,">0") -> 0 | N19: =COUNTIFS(BRAVO!RANK,"3CL",BRAVO!NATURE,"UNIFORM",BRAVO!N:N,">0") -> 0 | O19: =COUNTIFS(BRAVO!RANK,"4CL",BRAVO!NATURE,"UNIFORM",BRAVO!REMARKS,"ONGOING") -> 0 | Q19: UNIFORM | R19: =COUNTIFS(CHARLIE!RANK,"1CL",CHARLIE!NATURE,"UNIFORM",CHARLIE!N:N,">0") -> 0 | S19: =COUNTIFS(CHARLIE!RANK,"2CL",CHARLIE!NATURE,"UNIFORM",CHARLIE!N:N,">0") -> 0 | T19: =COUNTIFS(CHARLIE!RANK,"3CL",CHARLIE!NATURE,"UNIFORM",CHARLIE!N:N,">0") -> 0 | U19: =COUNTIFS(CHARLIE!RANK,"4CL",CHARLIE!NATURE,"UNIFORM",CHARLIE!REMARKS,"ONGOING") -> 0 | W19: UNIFORM | X19: =COUNTIFS(DELTA!RANK,"1CL",DELTA!NATURE,"UNIFORM",DELTA!N:N,">0") -> 0 | Y19: =COUNTIFS(DELTA!RANK,"2CL",DELTA!NATURE,"UNIFORM",DELTA!N:N,">0") -> 0 | Z19: =COUNTIFS(DELTA!RANK,"3CL",DELTA!NATURE,"UNIFORM",DELTA!N:N,">0") -> 0 | AA19: =COUNTIFS(DELTA!RANK,"4CL",DELTA!NATURE,"UNIFORM",DELTA!REMARKS,"ONGOING") -> 0 | AC19: UNIFORM | AD19: =COUNTIFS(ECHO!RANK,"1CL",ECHO!NATURE,"UNIFORM",ECHO!M:M,">0") -> 0 | AE19: =COUNTIFS(ECHO!RANK,"2CL",ECHO!NATURE,"UNIFORM",ECHO!M:M,">0") -> 0 | AF19: =COUNTIFS(ECHO!RANK,"3CL",ECHO!NATURE,"UNIFORM",ECHO!M:M,">0") -> 0 | AG19: =COUNTIFS(ECHO!RANK,"4CL",ECHO!NATURE,"UNIFORM",ECHO!REMARKS,"ONGOING") -> 0 | AI19: UNIFORM | AJ19: =COUNTIFS(FOXTROT!RANK,"1CL",FOXTROT!NATURE,"UNIFORM",FOXTROT!N:N,">0") -> 0 | AK19: =COUNTIFS(FOXTROT!RANK,"2CL",FOXTROT!NATURE,"UNIFORM",FOXTROT!N:N,">0") -> 0 | AL19: =COUNTIFS(FOXTROT!RANK,"3CL",FOXTROT!NATURE,"UNIFORM",FOXTROT!N:N,">0") -> 0 | AM19: =COUNTIFS(FOXTROT!RANK,"4CL",FOXTROT!NATURE,"UNIFORM",FOXTROT!REMARKS,"ONGOING") -> 0 | AO19: UNIFORM | AP19: =COUNTIFS(GOLF!RANK,"1CL",GOLF!NATURE,"UNIFORM",GOLF!N:N,">0") -> 0 | AQ19: =COUNTIFS(GOLF!RANK,"2CL",GOLF!NATURE,"UNIFORM",GOLF!N:N,">0") -> 0 | AR19: =COUNTIFS(GOLF!RANK,"3CL",GOLF!NATURE,"UNIFORM",GOLF!N:N,">0") -> 0 | AS19: =COUNTIFS(GOLF!RANK,"4CL",GOLF!NATURE,"UNIFORM",GOLF!REMARKS,"ONGOING") -> 0 | AU19: UNIFORM | AV19: =COUNTIFS(HAWK!RANK,"1CL",HAWK!NATURE,"UNIFORM",HAWK!N:N,">0") -> 0 | AW19: =COUNTIFS(HAWK!RANK,"2CL",HAWK!NATURE,"UNIFORM",HAWK!N:N,">0") -> 0 | AX19: =COUNTIFS(HAWK!RANK,"3CL",HAWK!NATURE,"UNIFORM",HAWK!N:N,">0") -> 0 | AY19: =COUNTIFS(HAWK!RANK,"4CL",HAWK!NATURE,"UNIFORM",HAWK!REMARKS,"ONGOING") -> 0 | BA19: UNIFORM | BB19: =COUNTIFS(#REF!,"1CL",#REF!,"UNIFORM",#REF!,"ONGOING") -> 0 | BC19: =COUNTIFS(#REF!,"2CL",#REF!,"UNIFORM",#REF!,"ONGOING") -> 0 | BD19: =COUNTIFS(#REF!,"3CL",#REF!,"UNIFORM",#REF!,"ONGOING") -> 0 | BE19: =COUNTIFS(#REF!,"4CL",#REF!,"UNIFORM",#REF!,"ONGOING") -> 0
E20: TOTAL | F20: =SUM(F10:F19) -> 0 | G20: =SUM(G10:G19) -> 4 | H20: =SUM(H10:H19) -> 2 | I20: =SUM(I10:I19) -> 0 | K20: TOTAL | L20: =SUM(L10:L18) -> 0 | M20: =SUM(M10:M19) -> 0 | N20: =SUM(N10:N19) -> 0 | O20: =SUM(O10:O19) -> 0 | Q20: TOTAL | R20: =sum(R10:R19) -> 3 | S20: =sum(S10:S19) -> 5 | T20: =sum(T10:T19) -> 16 | U20: =sum(U10:U19) -> 0 | W20: TOTAL | X20: =SUM(X10:X19) -> 1 | Y20: =SUM(Y10:Y19) -> 4 | Z20: =SUM(Z10:Z19) -> 7 | AA20: =SUM(AA10:AA19) -> 3 | AC20: TOTAL | AD20: =SUm(AD10:AD19) -> 0 | AE20: =SUm(AE10:AE19) -> 2 | AF20: =SUm(AF10:AF19) -> 0 | AG20: =SUm(AG10:AG19) -> 0 | AI20: TOTAL | AJ20: =SUM(AJ10:AJ19) -> 0 | AK20: =SUM(AK10:AK19) -> 3 | AL20: =SUM(AL10:AL19) -> 0 | AM20: =SUM(AM10:AM19) -> 8 | AO20: TOTAL | AP20: =Sum(AP10:AP19) -> 0 | AQ20: =Sum(AQ10:AQ19) -> 0 | AR20: =Sum(AR10:AR19) -> 0 | AS20: =Sum(AS10:AS19) -> 0 | AU20: TOTAL | AV20: =SUM(AV10:AV19) -> 0 | AW20: =SUM(AW10:AW19) -> 1 | AX20: =SUM(AX10:AX19) -> 1 | AY20: =SUM(AY10:AY19) -> 2 | BA20: TOTAL | BB20: =SUM(BB10:BB19) -> 0 | BC20: =SUM(BC10:BC19) -> 0 | BD20: =SUM(BD10:BD19) -> 0 | BE20: =SUM(BE10:BE19) -> 0
E23: PER CLASS OF OFFENSES | K23: PER CLASS OF OFFENSES | Q23: PER CLASS OF OFFENSES | W23: PER CLASS OF OFFENSES | AC23: PER CLASS OF OFFENSES | AI23: PER CLASS OF OFFENSES | AO23: PER CLASS OF OFFENSES | AU23: PER CLASS OF OFFENSES | BA23: PER CLASS OF OFFENSES
E25: CLASS OF OFFENSE | F25: 1CL | G25: 2CL | H25: 3CL | I25: 4CL | K25: CLASS OF OFFENSE | L25: 1CL | M25: 2CL | N25: 3CL | O25: 4CL | Q25: CLASS OF OFFENSE | R25: 1CL | S25: 2CL | T25: 3CL | U25: 4CL | W25: CLASS OF OFFENSE | X25: 1CL | Y25: 2CL | Z25: 3CL | AA25: 4CL | AC25: CLASS OF OFFENSE | AD25: 1CL | AE25: 2CL | AF25: 3CL | AG25: 4CL | AI25: CLASS OF OFFENSE | AJ25: 1CL | AK25: 2CL | AL25: 3CL | AM25: 4CL | AO25: CLASS OF OFFENSE | AP25: 1CL | AQ25: 2CL | AR25: 3CL | AS25: 4CL | AU25: CLASS OF OFFENSE | AV25: 1CL | AW25: 2CL | AX25: 3CL | AY25: 4CL | BA25: CLASS OF OFFENSE | BB25: 1CL | BC25: 2CL | BD25: 3CL | BE25: 4CL
E26: I | F26: =COUNTIFS(CLASS,"I",RANK,"1CL",REMARKS, "ONGOING/CONFINED")+COUNTIFS(CLASS,"I", RANK,"1CL",REMARKS, "ONGOING") -> 1 | G26: =COUNTIFS(CLASS,"I",RANK,"2CL",REMARKS, "ONGOING/CONFINED")+COUNTIFS(CLASS,"I", RANK,"2CL",REMARKS, "ONGOING") -> 0 | H26: =COUNTIFS(CLASS,"I",RANK,"3CL",REMARKS, "ONGOING/CONFINED")+COUNTIFS(CLASS,"I", RANK,"3CL",REMARKS, "ONGOING") -> 0 | I26: =COUNTIFS(CLASS,"I",RANK,"4CL",REMARKS,"ONGOING") -> 0 | K26: I | L26: =COUNTIFS(BRAVO!CLASS,"I",BRAVO!RANK,"1CL",BRAVO!REMARKS, "ONGOING/CONFINED")+COUNTIFS(BRAVO!CLASS,"I", BRAVO!RANK,"1CL",BRAVO!REMARKS, "ONGOING") -> 0 | M26: =COUNTIFS(BRAVO!CLASS,"I",BRAVO!RANK,"2CL",BRAVO!REMARKS, "ONGOING/CONFINED")+COUNTIFS(BRAVO!CLASS,"I", BRAVO!RANK,"2CL",BRAVO!REMARKS, "ONGOING") -> 0 | N26: =COUNTIFS(BRAVO!CLASS,"I",BRAVO!RANK,"3CL",BRAVO!REMARKS, "ONGOING/CONFINED")+COUNTIFS(BRAVO!CLASS,"I", BRAVO!RANK,"3CL",BRAVO!REMARKS, "ONGOING") -> 0 | O26: =COUNTIFS(BRAVO!CLASS,"I",BRAVO!RANK,"4CL",BRAVO!REMARKS,"ONGOING") -> 0 | Q26: I | R26: =COUNTIFS(CHARLIE!CLASS,"I",CHARLIE!RANK,"1CL",CHARLIE!REMARKS, "ONGOING/CONFINED")+COUNTIFS(CHARLIE!CLASS,"I", CHARLIE!RANK,"1CL",CHARLIE!REMARKS, "ONGOING")+COUNTIFS(CHARLIE!CLASS,"I", CHARLIE!RANK,"1CL",CHARLIE!REMARKS, "CONFINED") -> 0 | S26: =COUNTIFS(CHARLIE!CLASS,"I",CHARLIE!RANK,"2CL",CHARLIE!REMARKS, "ONGOING/CONFINED")+COUNTIFS(CHARLIE!CLASS,"I", CHARLIE!RANK,"2CL",CHARLIE!REMARKS, "ONGOING")+COUNTIFS(CHARLIE!CLASS,"I", CHARLIE!RANK,"2CL",CHARLIE!REMARKS, "CONFINED") -> 0 | T26: =COUNTIFS(CHARLIE!CLASS,"I",CHARLIE!RANK,"3CL",CHARLIE!REMARKS, "ONGOING/CONFINED")+COUNTIFS(CHARLIE!CLASS,"I", CHARLIE!RANK,"3CL",CHARLIE!REMARKS, "ONGOING")+COUNTIFS(CHARLIE!CLASS,"I", CHARLIE!RANK,"3CL",CHARLIE!REMARKS, "CONFINED") -> 1 | U26: =COUNTIFS(CHARLIE!CLASS,"I",CHARLIE!RANK,"4CL",CHARLIE!REMARKS,"ONGOING") -> 0 | W26: I | X26: =COUNTIFS(DELTA!CLASS,"I",DELTA!RANK,"1CL",DELTA!REMARKS, "ONGOING/CONFINED")+COUNTIFS(DELTA!CLASS,"I", DELTA!RANK,"1CL",DELTA!REMARKS, "ONGOING")+COUNTIFS(DELTA!CLASS,"I", DELTA!RANK,"1CL",DELTA!REMARKS, "CONFINED") -> 0 | Y26: =COUNTIFS(DELTA!CLASS,"I",DELTA!RANK,"2CL",DELTA!REMARKS, "ONGOING/CONFINED")+COUNTIFS(DELTA!CLASS,"I", DELTA!RANK,"2CL",DELTA!REMARKS, "ONGOING")+COUNTIFS(DELTA!CLASS,"I", DELTA!RANK,"2CL",DELTA!REMARKS, "CONFINED") -> 0 | Z26: =COUNTIFS(DELTA!CLASS,"I",DELTA!RANK,"3CL",DELTA!REMARKS, "ONGOING/CONFINED")+COUNTIFS(DELTA!CLASS,"I", DELTA!RANK,"3CL",DELTA!REMARKS, "ONGOING")+COUNTIFS(DELTA!CLASS,"I", DELTA!RANK,"3CL",DELTA!REMARKS, "CONFINED") -> 0 | AA26: =COUNTIFS(DELTA!CLASS,"I",DELTA!RANK,"4CL",DELTA!REMARKS,"ONGOING") -> 0 | AC26: I | AD26: =COUNTIFS(ECHO!CLASS,"I",ECHO!RANK,"1CL",ECHO!REMARKS, "ONGOING/CONFINED")+COUNTIFS(ECHO!CLASS,"I", ECHO!RANK,"1CL",ECHO!REMARKS, "ONGOING")+COUNTIFS(ECHO!CLASS,"I", ECHO!RANK,"1CL",ECHO!REMARKS, "CONFINED") -> 0 | AE26: =COUNTIFS(ECHO!CLASS,"I",ECHO!RANK,"2CL",ECHO!REMARKS, "ONGOING/CONFINED")+COUNTIFS(ECHO!CLASS,"I", ECHO!RANK,"2CL",ECHO!REMARKS, "ONGOING")+COUNTIFS(ECHO!CLASS,"I", ECHO!RANK,"2CL",ECHO!REMARKS, "CONFINED") -> 0 | AF26: =COUNTIFS(ECHO!CLASS,"I",ECHO!RANK,"3CL",ECHO!REMARKS, "ONGOING/CONFINED")+COUNTIFS(ECHO!CLASS,"I", ECHO!RANK,"3CL",ECHO!REMARKS, "ONGOING")+COUNTIFS(ECHO!CLASS,"I", ECHO!RANK,"3CL",ECHO!REMARKS, "CONFINED") -> 0 | AG26: =COUNTIFS(ECHO!CLASS,"I",ECHO!RANK,"4CL",ECHO!REMARKS,"ONGOING") -> 0 | AI26: I | AJ26: =COUNTIFS(FOXTROT!CLASS,"I",FOXTROT!RANK,"1CL",FOXTROT!REMARKS, "ONGOING/CONFINED")+COUNTIFS(FOXTROT!CLASS,"I", FOXTROT!RANK,"1CL",FOXTROT!REMARKS, "ONGOING")+COUNTIFS(FOXTROT!CLASS,"I", FOXTROT!RANK,"1CL",FOXTROT!REMARKS, "CONFINED") -> 0 | AK26: =COUNTIFS(FOXTROT!CLASS,"I",FOXTROT!RANK,"2CL",FOXTROT!REMARKS, "ONGOING/CONFINED")+COUNTIFS(FOXTROT!CLASS,"I", FOXTROT!RANK,"2CL",FOXTROT!REMARKS, "ONGOING")+COUNTIFS(FOXTROT!CLASS,"I", FOXTROT!RANK,"2CL",FOXTROT!REMARKS, "CONFINED") -> 0 | AL26: =COUNTIFS(FOXTROT!CLASS,"I",FOXTROT!RANK,"3CL",FOXTROT!REMARKS, "ONGOING/CONFINED")+COUNTIFS(FOXTROT!CLASS,"I", FOXTROT!RANK,"3CL",FOXTROT!REMARKS, "ONGOING")+COUNTIFS(FOXTROT!CLASS,"I", FOXTROT!RANK,"3CL",FOXTROT!REMARKS, "CONFINED") -> 0 | AM26: =COUNTIFS(FOXTROT!CLASS,"I",FOXTROT!RANK,"4CL",FOXTROT!REMARKS,"ONGOING") -> 0 | AO26: I | AP26: =COUNTIFS(GOLF!CLASS,"I",GOLF!RANK,"3CL",GOLF!REMARKS, "ONGOING/CONFINED")+COUNTIFS(GOLF!CLASS,"I", GOLF!RANK,"3CL",GOLF!REMARKS, "ONGOING")+COUNTIFS(GOLF!CLASS,"I", GOLF!RANK,"3CL",GOLF!REMARKS, "CONFINED") -> 0 | AQ26: =COUNTIFS(GOLF!CLASS,"I",GOLF!RANK,"2CL",GOLF!REMARKS, "ONGOING/CONFINED")+COUNTIFS(GOLF!CLASS,"I", GOLF!RANK,"2CL",GOLF!REMARKS, "ONGOING")+COUNTIFS(GOLF!CLASS,"I", GOLF!RANK,"2CL",GOLF!REMARKS, "CONFINED") -> 0 | AR26: =COUNTIFS(GOLF!CLASS,"I",GOLF!RANK,"3CL",GOLF!REMARKS, "ONGOING/CONFINED")+COUNTIFS(GOLF!CLASS,"I", GOLF!RANK,"3CL",GOLF!REMARKS, "ONGOING")+COUNTIFS(GOLF!CLASS,"I", GOLF!RANK,"3CL",GOLF!REMARKS, "CONFINED") -> 0 | AS26: =COUNTIFS(GOLF!CLASS,"I",GOLF!RANK,"4CL",GOLF!REMARKS,"ONGOING") -> 0 | AU26: I | AV26: =COUNTIFS(HAWK!CLASS,"I",HAWK!RANK,"1CL",HAWK!REMARKS, "ONGOING/CONFINED")+COUNTIFS(HAWK!CLASS,"I", HAWK!RANK,"1CL",HAWK!REMARKS, "ONGOING")+COUNTIFS(HAWK!CLASS,"I", HAWK!RANK,"1CL",HAWK!REMARKS, "CONFINED") -> 0 | AW26: =COUNTIFS(HAWK!CLASS,"I",HAWK!RANK,"2CL",HAWK!REMARKS, "ONGOING/CONFINED")+COUNTIFS(HAWK!CLASS,"I", HAWK!RANK,"2CL",HAWK!REMARKS, "ONGOING")+COUNTIFS(HAWK!CLASS,"I", HAWK!RANK,"2CL",HAWK!REMARKS, "CONFINED") -> 1 | AX26: =COUNTIFS(HAWK!CLASS,"I",HAWK!RANK,"3CL",HAWK!REMARKS, "ONGOING/CONFINED")+COUNTIFS(HAWK!CLASS,"I", HAWK!RANK,"3CL",HAWK!REMARKS, "ONGOING")+COUNTIFS(HAWK!CLASS,"I", HAWK!RANK,"3CL",HAWK!REMARKS, "CONFINED") -> 0 | AY26: =COUNTIFS(HAWK!CLASS,"I",HAWK!RANK,"4CL",HAWK!REMARKS,"ONGOING") -> 0 | BA26: I | BB26: =COUNTIFS(#REF!,"I",#REF!,"1CL",#REF!,"ONGOING") -> 0 | BC26: =COUNTIFS(#REF!,"I",#REF!,"2CL",#REF!,"ONGOING") -> 0 | BD26: =COUNTIFS(#REF!,"I",#REF!,"3CL",#REF!,"ONGOING") -> 0 | BE26: =COUNTIFS(#REF!,"I",#REF!,"4CL",#REF!,"ONGOING") -> 0
E28: II | F28: =COUNTIFS(CLASS,"II",RANK,"1CL",REMARKS, "ONGOING/CONFINED")+COUNTIFS(CLASS,"II", RANK,"1CL",REMARKS, "ONGOING") -> 0 | G28: =COUNTIFS(CLASS,"II",RANK,"2CL",REMARKS, "ONGOING/CONFINED")+COUNTIFS(CLASS,"II", RANK,"2CL",REMARKS, "ONGOING") -> 10 | H28: =COUNTIFS(CLASS,"II",RANK,"3CL",REMARKS, "ONGOING/CONFINED")+COUNTIFS(CLASS,"II", RANK,"3CL",REMARKS, "ONGOING") -> 3 | I28: =COUNTIFS(CLASS,"II",RANK,"4CL",REMARKS,"ONGOING") -> 0 | K28: II | L28: =COUNTIFS(BRAVO!CLASS,"II",BRAVO!RANK,"1CL",BRAVO!REMARKS, "ONGOING/CONFINED")+COUNTIFS(BRAVO!CLASS,"II", BRAVO!RANK,"1CL",BRAVO!REMARKS, "ONGOING") -> 0 | M28: =COUNTIFS(BRAVO!CLASS,"II",BRAVO!RANK,"2CL",BRAVO!REMARKS, "ONGOING/CONFINED")+COUNTIFS(BRAVO!CLASS,"II", BRAVO!RANK,"2CL",BRAVO!REMARKS, "ONGOING") -> 0 | N28: =COUNTIFS(BRAVO!CLASS,"II",BRAVO!RANK,"3CL",BRAVO!REMARKS, "ONGOING/CONFINED")+COUNTIFS(BRAVO!CLASS,"II", BRAVO!RANK,"3CL",BRAVO!REMARKS, "ONGOING") -> 0 | O28: =COUNTIFS(BRAVO!CLASS,"II",BRAVO!RANK,"4CL",BRAVO!REMARKS,"ONGOING") -> 0 | Q28: II | R28: =COUNTIFS(CHARLIE!CLASS,"II",CHARLIE!RANK,"1CL",CHARLIE!REMARKS, "ONGOING/CONFINED")+COUNTIFS(CHARLIE!CLASS,"II", CHARLIE!RANK,"1CL",CHARLIE!REMARKS, "ONGOING")+COUNTIFS(CHARLIE!CLASS,"II", CHARLIE!RANK,"1CL",CHARLIE!REMARKS, "CONFINED") -> 0 | S28: =COUNTIFS(CHARLIE!CLASS,"II",CHARLIE!RANK,"2CL",CHARLIE!REMARKS, "ONGOING/CONFINED")+COUNTIFS(CHARLIE!CLASS,"II", CHARLIE!RANK,"2CL",CHARLIE!REMARKS, "ONGOING")+COUNTIFS(CHARLIE!CLASS,"II", CHARLIE!RANK,"2CL",CHARLIE!REMARKS, "CONFINED") -> 0 | T28: =COUNTIFS(CHARLIE!CLASS,"II",CHARLIE!RANK,"3CL",CHARLIE!REMARKS, "ONGOING/CONFINED")+COUNTIFS(CHARLIE!CLASS,"II", CHARLIE!RANK,"3CL",CHARLIE!REMARKS, "ONGOING")+COUNTIFS(CHARLIE!CLASS,"II", CHARLIE!RANK,"3CL",CHARLIE!REMARKS, "CONFINED") -> 4 | U28: =COUNTIFS(CHARLIE!CLASS,"II",CHARLIE!RANK,"4CL",CHARLIE!REMARKS,"ONGOING") -> 0 | W28: II | X28: =COUNTIFS(DELTA!CLASS,"II",DELTA!RANK,"1CL",DELTA!REMARKS, "ONGOING/CONFINED")+COUNTIFS(DELTA!CLASS,"II", DELTA!RANK,"1CL",DELTA!REMARKS, "ONGOING")+COUNTIFS(DELTA!CLASS,"II", DELTA!RANK,"1CL",DELTA!REMARKS, "CONFINED") -> 0 | Y28: =COUNTIFS(DELTA!CLASS,"II",DELTA!RANK,"2CL",DELTA!REMARKS, "ONGOING/CONFINED")+COUNTIFS(DELTA!CLASS,"II", DELTA!RANK,"2CL",DELTA!REMARKS, "ONGOING")+COUNTIFS(DELTA!CLASS,"II", DELTA!RANK,"2CL",DELTA!REMARKS, "CONFINED") -> 4 | Z28: =COUNTIFS(DELTA!CLASS,"II",DELTA!RANK,"3CL",DELTA!REMARKS, "ONGOING/CONFINED")+COUNTIFS(DELTA!CLASS,"II", DELTA!RANK,"3CL",DELTA!REMARKS, "ONGOING")+COUNTIFS(DELTA!CLASS,"II", DELTA!RANK,"3CL",DELTA!REMARKS, "CONFINED") -> 0 | AA28: =COUNTIFS(DELTA!CLASS,"II",DELTA!RANK,"4CL",DELTA!REMARKS,"ONGOING") -> 0 | AC28: II | AD28: =COUNTIFS(ECHO!CLASS,"II",ECHO!RANK,"1CL",ECHO!REMARKS, "ONGOING/CONFINED")+COUNTIFS(ECHO!CLASS,"II", ECHO!RANK,"1CL",ECHO!REMARKS, "ONGOING")+COUNTIFS(ECHO!CLASS,"II", ECHO!RANK,"1CL",ECHO!REMARKS, "CONFINED") -> 1 | AE28: =COUNTIFS(ECHO!CLASS,"II",ECHO!RANK,"2CL",ECHO!REMARKS, "ONGOING/CONFINED")+COUNTIFS(ECHO!CLASS,"II", ECHO!RANK,"2CL",ECHO!REMARKS, "ONGOING")+COUNTIFS(ECHO!CLASS,"II", ECHO!RANK,"2CL",ECHO!REMARKS, "CONFINED") -> 1 | AF28: =COUNTIFS(ECHO!CLASS,"II",ECHO!RANK,"3CL",ECHO!REMARKS, "ONGOING/CONFINED")+COUNTIFS(ECHO!CLASS,"II", ECHO!RANK,"3CL",ECHO!REMARKS, "ONGOING")+COUNTIFS(ECHO!CLASS,"II", ECHO!RANK,"3CL",ECHO!REMARKS, "CONFINED") -> 1 | AG28: =COUNTIFS(ECHO!CLASS,"II",ECHO!RANK,"4CL",ECHO!REMARKS,"ONGOING") -> 0 | AI28: II | AJ28: =COUNTIFS(FOXTROT!CLASS,"II",FOXTROT!RANK,"1CL",FOXTROT!REMARKS, "ONGOING/CONFINED")+COUNTIFS(FOXTROT!CLASS,"II", FOXTROT!RANK,"1CL",FOXTROT!REMARKS, "ONGOING")+COUNTIFS(FOXTROT!CLASS,"II", FOXTROT!RANK,"1CL",FOXTROT!REMARKS, "CONFINED") -> 0 | AK28: =COUNTIFS(FOXTROT!CLASS,"II",FOXTROT!RANK,"2CL",FOXTROT!REMARKS, "ONGOING/CONFINED")+COUNTIFS(FOXTROT!CLASS,"II", FOXTROT!RANK,"2CL",FOXTROT!REMARKS, "ONGOING")+COUNTIFS(FOXTROT!CLASS,"II", FOXTROT!RANK,"2CL",FOXTROT!REMARKS, "CONFINED") -> 1 | AL28: =COUNTIFS(FOXTROT!CLASS,"II",FOXTROT!RANK,"3CL",FOXTROT!REMARKS, "ONGOING/CONFINED")+COUNTIFS(FOXTROT!CLASS,"II", FOXTROT!RANK,"3CL",FOXTROT!REMARKS, "ONGOING")+COUNTIFS(FOXTROT!CLASS,"II", FOXTROT!RANK,"3CL",FOXTROT!REMARKS, "CONFINED") -> 0 | AM28: =COUNTIFS(FOXTROT!CLASS,"II",FOXTROT!RANK,"4CL",FOXTROT!REMARKS,"ONGOING") -> 1 | AO28: II | AP28: =COUNTIFS(GOLF!CLASS,"II",GOLF!RANK,"3CL",GOLF!REMARKS, "ONGOING/CONFINED")+COUNTIFS(GOLF!CLASS,"II", GOLF!RANK,"3CL",GOLF!REMARKS, "ONGOING")+COUNTIFS(GOLF!CLASS,"II", GOLF!RANK,"3CL",GOLF!REMARKS, "CONFINED") -> 0 | AQ28: =COUNTIFS(GOLF!CLASS,"II",GOLF!RANK,"2CL",GOLF!REMARKS, "ONGOING/CONFINED")+COUNTIFS(GOLF!CLASS,"II", GOLF!RANK,"2CL",GOLF!REMARKS, "ONGOING")+COUNTIFS(GOLF!CLASS,"II", GOLF!RANK,"2CL",GOLF!REMARKS, "CONFINED") -> 1 | AR28: =COUNTIFS(GOLF!CLASS,"II",GOLF!RANK,"3CL",GOLF!REMARKS, "ONGOING/CONFINED")+COUNTIFS(GOLF!CLASS,"II", GOLF!RANK,"3CL",GOLF!REMARKS, "ONGOING")+COUNTIFS(GOLF!CLASS,"II", GOLF!RANK,"3CL",GOLF!REMARKS, "CONFINED") -> 0 | AS28: =COUNTIFS(GOLF!CLASS,"II",GOLF!RANK,"4CL",GOLF!REMARKS,"ONGOING") -> 0 | AU28: II | AV28: =COUNTIFS(HAWK!CLASS,"II",HAWK!RANK,"1CL",HAWK!REMARKS, "ONGOING/CONFINED")+COUNTIFS(HAWK!CLASS,"II", HAWK!RANK,"1CL",HAWK!REMARKS, "ONGOING")+COUNTIFS(HAWK!CLASS,"II", HAWK!RANK,"1CL",HAWK!REMARKS, "CONFINED") -> 0 | AW28: =COUNTIFS(HAWK!CLASS,"II",HAWK!RANK,"2CL",HAWK!REMARKS, "ONGOING/CONFINED")+COUNTIFS(HAWK!CLASS,"II", HAWK!RANK,"2CL",HAWK!REMARKS, "ONGOING")+COUNTIFS(HAWK!CLASS,"II", HAWK!RANK,"2CL",HAWK!REMARKS, "CONFINED") -> 0 | AX28: =COUNTIFS(HAWK!CLASS,"II",HAWK!RANK,"3CL",HAWK!REMARKS, "ONGOING/CONFINED")+COUNTIFS(HAWK!CLASS,"II", HAWK!RANK,"3CL",HAWK!REMARKS, "ONGOING")+COUNTIFS(HAWK!CLASS,"II", HAWK!RANK,"3CL",HAWK!REMARKS, "CONFINED") -> 0 | AY28: =COUNTIFS(HAWK!CLASS,"II",HAWK!RANK,"4CL",HAWK!REMARKS,"ONGOING") -> 0 | BA28: II | BB28: =COUNTIFS(#REF!,"II",#REF!,"1CL",#REF!,"ONGOING") -> 0 | BC28: =COUNTIFS(#REF!,"II",#REF!,"2CL",#REF!,"ONGOING") -> 0 | BD28: =COUNTIFS(#REF!,"II",#REF!,"3CL",#REF!,"ONGOING") -> 0 | BE28: =COUNTIFS(#REF!,"II",#REF!,"4CL",#REF!,"ONGOING") -> 0
E30: III | F30: =COUNTIFS(CLASS,"III",RANK,"1CL",REMARKS, "ONGOING/CONFINED")+COUNTIFS(CLASS,"III", RANK,"1CL",REMARKS, "ONGOING") -> 1 | G30: =COUNTIFS(CLASS,"III",RANK,"2CL",REMARKS, "ONGOING/CONFINED")+COUNTIFS(CLASS,"III", RANK,"2CL",REMARKS, "ONGOING") -> 2 | H30: =COUNTIFS(CLASS,"III",RANK,"3CL",REMARKS, "ONGOING/CONFINED")+COUNTIFS(CLASS,"III", RANK,"3CL",REMARKS, "ONGOING") -> 0 | I30: =COUNTIFS(CLASS,"III",RANK,"4CL",REMARKS,"ONGOING") -> 0 | K30: III | L30: =COUNTIFS(BRAVO!CLASS,"III",BRAVO!RANK,"1CL",BRAVO!REMARKS, "ONGOING/CONFINED")+COUNTIFS(BRAVO!CLASS,"III", BRAVO!RANK,"1CL",BRAVO!REMARKS, "ONGOING") -> 0 | M30: =COUNTIFS(BRAVO!CLASS,"III",BRAVO!RANK,"2CL",BRAVO!REMARKS, "ONGOING/CONFINED")+COUNTIFS(BRAVO!CLASS,"III", BRAVO!RANK,"2CL",BRAVO!REMARKS, "ONGOING") -> 0 | N30: =COUNTIFS(BRAVO!CLASS,"III",BRAVO!RANK,"3CL",BRAVO!REMARKS, "ONGOING/CONFINED")+COUNTIFS(BRAVO!CLASS,"III", BRAVO!RANK,"3CL",BRAVO!REMARKS, "ONGOING") -> 0 | O30: =COUNTIFS(BRAVO!CLASS,"III",BRAVO!RANK,"4CL",BRAVO!REMARKS,"ONGOING") -> 0 | Q30: III | R30: =COUNTIFS(CHARLIE!CLASS,"III",CHARLIE!RANK,"1CL",CHARLIE!REMARKS, "ONGOING/CONFINED")+COUNTIFS(CHARLIE!CLASS,"III", CHARLIE!RANK,"1CL",CHARLIE!REMARKS, "ONGOING")+COUNTIFS(CHARLIE!CLASS,"III", CHARLIE!RANK,"1CL",CHARLIE!REMARKS, "CONFINED") -> 0 | S30: =COUNTIFS(CHARLIE!CLASS,"IIi",CHARLIE!RANK,"2CL",CHARLIE!REMARKS, "ONGOING/CONFINED")+COUNTIFS(CHARLIE!CLASS,"IiI", CHARLIE!RANK,"2CL",CHARLIE!REMARKS, "ONGOING")+COUNTIFS(CHARLIE!CLASS,"IiI", CHARLIE!RANK,"2CL",CHARLIE!REMARKS, "CONFINED") -> 0 | T30: =COUNTIFS(CHARLIE!CLASS,"III",CHARLIE!RANK,"3CL",CHARLIE!REMARKS, "ONGOING/CONFINED")+COUNTIFS(CHARLIE!CLASS,"III", CHARLIE!RANK,"3CL",CHARLIE!REMARKS, "ONGOING")+COUNTIFS(CHARLIE!CLASS,"III", CHARLIE!RANK,"3CL",CHARLIE!REMARKS, "CONFINED") -> 10 | U30: =COUNTIFS(CHARLIE!CLASS,"III",CHARLIE!RANK,"4CL",CHARLIE!REMARKS,"ONGOING") -> 0 | W30: III | X30: =COUNTIFS(DELTA!CLASS,"III",DELTA!RANK,"1CL",DELTA!REMARKS, "ONGOING/CONFINED")+COUNTIFS(DELTA!CLASS,"III", DELTA!RANK,"1CL",DELTA!REMARKS, "ONGOING")+COUNTIFS(DELTA!CLASS,"III", DELTA!RANK,"1CL",DELTA!REMARKS, "CONFINED") -> 1 | Y30: =COUNTIFS(DELTA!CLASS,"III",DELTA!RANK,"2CL",DELTA!REMARKS, "ONGOING/CONFINED")+COUNTIFS(DELTA!CLASS,"III", DELTA!RANK,"2CL",DELTA!REMARKS, "ONGOING")+COUNTIFS(DELTA!CLASS,"III", DELTA!RANK,"2CL",DELTA!REMARKS, "CONFINED") -> 2 | Z30: =COUNTIFS(DELTA!CLASS,"III",DELTA!RANK,"3CL",DELTA!REMARKS, "ONGOING/CONFINED")+COUNTIFS(DELTA!CLASS,"III", DELTA!RANK,"3CL",DELTA!REMARKS, "ONGOING")+COUNTIFS(DELTA!CLASS,"III", DELTA!RANK,"3CL",DELTA!REMARKS, "CONFINED") -> 11 | AA30: =COUNTIFS(DELTA!CLASS,"III",DELTA!RANK,"4CL",DELTA!REMARKS,"ONGOING") -> 3 | AC30: III | AD30: =COUNTIFS(ECHO!CLASS,"III",ECHO!RANK,"1CL",ECHO!REMARKS, "ONGOING/CONFINED")+COUNTIFS(ECHO!CLASS,"III", ECHO!RANK,"1CL",ECHO!REMARKS, "ONGOING")+COUNTIFS(ECHO!CLASS,"III", ECHO!RANK,"1CL",ECHO!REMARKS, "CONFINED") -> 0 | AE30: =COUNTIFS(ECHO!CLASS,"III",ECHO!RANK,"2CL",ECHO!REMARKS, "ONGOING/CONFINED")+COUNTIFS(ECHO!CLASS,"III", ECHO!RANK,"2CL",ECHO!REMARKS, "ONGOING")+COUNTIFS(ECHO!CLASS,"III", ECHO!RANK,"2CL",ECHO!REMARKS, "CONFINED") -> 0 | AF30: =COUNTIFS(ECHO!CLASS,"III",ECHO!RANK,"3CL",ECHO!REMARKS, "ONGOING/CONFINED")+COUNTIFS(ECHO!CLASS,"III", ECHO!RANK,"3CL",ECHO!REMARKS, "ONGOING")+COUNTIFS(ECHO!CLASS,"III", ECHO!RANK,"3CL",ECHO!REMARKS, "CONFINED") -> 0 | AG30: =COUNTIFS(ECHO!CLASS,"III",ECHO!RANK,"4CL",ECHO!REMARKS,"ONGOING") -> 0 | AI30: III | AJ30: =COUNTIFS(FOXTROT!CLASS,"III",FOXTROT!RANK,"1CL",FOXTROT!REMARKS, "ONGOING/CONFINED")+COUNTIFS(FOXTROT!CLASS,"III", FOXTROT!RANK,"1CL",FOXTROT!REMARKS, "ONGOING")+COUNTIFS(FOXTROT!CLASS,"III", FOXTROT!RANK,"1CL",FOXTROT!REMARKS, "CONFINED") -> 0 | AK30: =COUNTIFS(FOXTROT!CLASS,"III",FOXTROT!RANK,"2CL",FOXTROT!REMARKS, "ONGOING/CONFINED")+COUNTIFS(FOXTROT!CLASS,"III", FOXTROT!RANK,"2CL",FOXTROT!REMARKS, "ONGOING")+COUNTIFS(FOXTROT!CLASS,"III", FOXTROT!RANK,"2CL",FOXTROT!REMARKS, "CONFINED") -> 2 | AL30: =COUNTIFS(FOXTROT!CLASS,"III",FOXTROT!RANK,"3CL",FOXTROT!REMARKS, "ONGOING/CONFINED")+COUNTIFS(FOXTROT!CLASS,"III", FOXTROT!RANK,"3CL",FOXTROT!REMARKS, "ONGOING")+COUNTIFS(FOXTROT!CLASS,"III", FOXTROT!RANK,"3CL",FOXTROT!REMARKS, "CONFINED") -> 0 | AM30: =COUNTIFS(FOXTROT!CLASS,"III",FOXTROT!RANK,"4CL",FOXTROT!REMARKS,"ONGOING") -> 7 | AO30: III | AP30: =COUNTIFS(GOLF!CLASS,"III",GOLF!RANK,"3CL",GOLF!REMARKS, "ONGOING/CONFINED")+COUNTIFS(GOLF!CLASS,"III", GOLF!RANK,"3CL",GOLF!REMARKS, "ONGOING")+COUNTIFS(GOLF!CLASS,"III", GOLF!RANK,"3CL",GOLF!REMARKS, "CONFINED") -> 0 | AQ30: =COUNTIFS(GOLF!CLASS,"III",GOLF!RANK,"2CL",GOLF!REMARKS, "ONGOING/CONFINED")+COUNTIFS(GOLF!CLASS,"III", GOLF!RANK,"2CL",GOLF!REMARKS, "ONGOING")+COUNTIFS(GOLF!CLASS,"III", GOLF!RANK,"2CL",GOLF!REMARKS, "CONFINED") -> 0 | AR30: =COUNTIFS(GOLF!CLASS,"III",GOLF!RANK,"3CL",GOLF!REMARKS, "ONGOING/CONFINED")+COUNTIFS(GOLF!CLASS,"III", GOLF!RANK,"3CL",GOLF!REMARKS, "ONGOING")+COUNTIFS(GOLF!CLASS,"III", GOLF!RANK,"3CL",GOLF!REMARKS, "CONFINED") -> 0 | AS30: =COUNTIFS(GOLF!CLASS,"III",GOLF!RANK,"4CL",GOLF!REMARKS,"ONGOING") -> 0 | AU30: III | AV30: =COUNTIFS(HAWK!CLASS,"III",HAWK!RANK,"1CL",HAWK!REMARKS, "ONGOING/CONFINED")+COUNTIFS(HAWK!CLASS,"III", HAWK!RANK,"1CL",HAWK!REMARKS, "ONGOING")+COUNTIFS(HAWK!CLASS,"III", HAWK!RANK,"1CL",HAWK!REMARKS, "CONFINED") -> 0 | AW30: =COUNTIFS(HAWK!CLASS,"III",HAWK!RANK,"2CL",HAWK!REMARKS, "ONGOING/CONFINED")+COUNTIFS(HAWK!CLASS,"III", HAWK!RANK,"2CL",HAWK!REMARKS, "ONGOING")+COUNTIFS(HAWK!CLASS,"III", HAWK!RANK,"2CL",HAWK!REMARKS, "CONFINED") -> 0 | AX30: =COUNTIFS(HAWK!CLASS,"III",HAWK!RANK,"3CL",HAWK!REMARKS, "ONGOING/CONFINED")+COUNTIFS(HAWK!CLASS,"III", HAWK!RANK,"3CL",HAWK!REMARKS, "ONGOING")+COUNTIFS(HAWK!CLASS,"III", HAWK!RANK,"3CL",HAWK!REMARKS, "CONFINED") -> 2 | AY30: =COUNTIFS(HAWK!CLASS,"III",HAWK!RANK,"4CL",HAWK!REMARKS,"ONGOING") -> 2 | BA30: III | BB30: =COUNTIFS(#REF!,"III",#REF!,"1CL",#REF!,"ONGOING") -> 0 | BC30: =COUNTIFS(#REF!,"III",#REF!,"2CL",#REF!,"ONGOING") -> 0 | BD30: =COUNTIFS(#REF!,"III",#REF!,"3CL",#REF!,"ONGOING") -> 0 | BE30: =COUNTIFS(#REF!,"III",#REF!,"4CL",#REF!,"ONGOING") -> 0
E32: TOTAL | F32: =SUM(F26:F31) -> 2 | G32: =SUM(G26:G31) -> 12 | H32: =SUM(H26:H31) -> 3 | I32: =SUM(I26:I31) -> 0 | K32: TOTAL | L32: =SUM(L26:L31) -> 0 | M32: =SUM(M26:M31) -> 0 | N32: =SUM(N26:N31) -> 0 | O32: =SUM(O26:O31) -> 0 | Q32: TOTAL | R32: =SUM(R26:R31) -> 0 | S32: =SUM(S26:S31) -> 0 | T32: =SUM(T26:T31) -> 15 | U32: =SUM(U26:U31) -> 0 | W32: TOTAL | X32: =SUM(X26:X31) -> 1 | Y32: =SUM(Y26:Y31) -> 6 | Z32: =SUM(Z26:Z31) -> 11 | AA32: =SUM(AA26:AA31) -> 3 | AC32: TOTAL | AD32: =sum(AD26:AD31) -> 1 | AE32: =sum(AE26:AE31) -> 1 | AF32: =sum(AF26:AF31) -> 1 | AG32: =sum(AG26:AG31) -> 0 | AI32: TOTAL | AJ32: =SUM(AJ26:AJ31) -> 0 | AK32: =SUM(AK26:AK31) -> 3 | AL32: =SUM(AL26:AL31) -> 0 | AM32: =SUM(AM26:AM31) -> 8 | AO32: TOTAL | AP32: =SUM(AP26:AP31) -> 0 | AQ32: =SUM(AQ26:AQ31) -> 1 | AR32: =SUM(AR26:AR31) -> 0 | AS32: =SUM(AS26:AS31) -> 0 | AU32: TOTAL | AV32: =SUM(AV26:AV31) -> 0 | AW32: =SUM(AW26:AW31) -> 1 | AX32: =SUM(AX26:AX31) -> 2 | AY32: =SUM(AY26:AY31) -> 2 | BA32: TOTAL | BB32: =SUM(BB26:BB31) -> 0 | BC32: =SUM(BC26:BC31) -> 0 | BD32: =SUM(BD26:BD31) -> 0 | BE32: =SUM(BE26:BE31) -> 0
E35: CONFINED CADETS | H35: TOURING/CONFINED | K35: CONFINED CADETS | N35: TOURING/CONFINED | Q35: CONFINED CADETS | T35: TOURING/CONFINED | W35: CONFINED CADETS | Z35: TOURING/CONFINED | AC35: CONFINED CADETS | AF35: TOURING/CONFINED | AI35: CONFINED CADETS | AL35: TOURING/CONFINED | AO35: CONFINED CADETS | AR35: TOURING/CONFINED | AU35: CONFINED CADETS | AX35: TOURING/CONFINED | BA35: CONFINED CADETS | BD35: TOURING/CONFINED
E37: 1CL | F37: =COUNTIFS(RANK,"1CL",CONFINEMENT,"YES") -> 1 | H37: 1CL | I37: =COUNTIFS(RANK,"1CL",CONFINEMENT,"YES",ALFA!N:N, ">0") -> 1 | K37: 1CL | L37: =COUNTIFS(BRAVO!RANK,"1CL",BRAVO!CONFINEMENT,"YES") -> 5 | N37: 1CL | O37: =COUNTIFS(BRAVO!RANK,"1CL",BRAVO!CONFINEMENT,"YES",BRAVO!N:N, ">0") -> 0 | Q37: 1CL | R37: =COUNTIFS(CHARLIE!RANK,"1CL",CHARLIE!CONFINEMENT,"YES") -> 14 | T37: 1CL | U37: =COUNTIFS(CHARLIE!RANK,"1CL",CHARLIE!CONFINEMENT,"YES" ,CHARLIE!N:N, ">0") -> 0 | W37: 1CL | X37: =COUNTIFS(DELTA!RANK,"1CL",DELTA!CONFINEMENT,"YES") -> 3 | Z37: 1CL | AA37: =COUNTIFS(DELTA!RANK,"1CL",DELTA!CONFINEMENT,"YES",DELTA!N:N, ">0") -> 0 | AC37: 1CL | AD37: =COUNTIFS(ECHO!RANK,"1CL",ECHO!CONFINEMENT,"YES") -> 9 | AF37: 1CL | AG37: =COUNTIFS(ECHO!RANK,"1CL",ECHO!CONFINEMENT,"YES",ECHO!M:M, ">0") -> 0 | AI37: 1CL | AJ37: =COUNTIFS(FOXTROT!RANK,"1CL",FOXTROT!CONFINEMENT,"YES") -> 0 | AL37: 1CL | AM37: =COUNTIFS(FOXTROT!RANK,"1CL",FOXTROT!CONFINEMENT,"YES",FOXTROT!N:N, ">0") -> 0 | AO37: 1CL | AP37: =COUNTIFS(GOLF!RANK,"1CL",GOLF!CONFINEMENT,"YES") -> 0 | AR37: 1CL | AS37: =COUNTIFS(GOLF!RANK,"1CL",GOLF!CONFINEMENT,"YES",GOLF!N:N, ">0") -> 0 | AU37: 1CL | AV37: =COUNTIFS(HAWK!RANK,"1CL",HAWK!CONFINEMENT,"YES") -> 10 | AX37: 1CL | AY37: =COUNTIFS(HAWK!RANK,"1CL",HAWK!CONFINEMENT,"YES",HAWK!N:N, ">0") -> 3 | BA37: 1CL | BB37: =COUNTIFS(#REF!,"1CL",#REF!,"YES") -> 0 | BD37: 1CL | BE37: =COUNTIFS(#REF!,"1CL",#REF!,"YES",CONDUCT!N:N, ">0") -> 0
